#dig label(dig) start(34;34;center)

,,,,,,,,,,,,,,,,,,,,,,,,,,,,,,,d,d,d,d,d
,,,,,,,,,,,,,,,,,,,,,,,,,,,,,,,d,h,r,,d
,,,,,,,,,d,d,d,,d,d,d,,d,d,d,,d,d,d,,d,d,d,,,,d,,,,d,,,,d,d,d,,d,d,d,,d,d,d,,d,d,d,,d,d,d
,,,,,,,,,d,d,d,,d,d,d,,d,d,d,,d,d,d,,d,d,d,,,,d,,r,h,d,,,,d,d,d,,d,d,d,,d,d,d,,d,d,d,,d,d,d
,,,,,,,,,d,d,d,,d,d,d,,d,d,d,,d,d,d,,d,d,d,,,,d,d,d,d,d,,,,d,d,d,,d,d,d,,d,d,d,,d,d,d,,d,d,d
,,,,,,,,,h,,h,,h,,h,,h,,h,,h,,h,,h,,h,,,,,,,,,,,,h,,h,,h,,h,,h,,h,,h,,h,,h,,h

,,,,,,,,,h,,h,,h,,h,,h,,h,,h,,h,,h,,h,,,,,,,,,,,,h,,h,,h,,h,,h,,h,,h,,h,,h,,h
,,,d,d,d,h,,h,d,d,d,,d,d,d,,d,d,d,,d,d,d,,d,d,d,,d,d,d,h,,h,d,d,d,,d,d,d,,d,d,d,,d,d,d,,d,d,d,,d,d,d,h,,h,d,d,d
,,,d,d,d,,,,d,d,d,,d,d,d,,d,d,d,,d,d,d,,d,d,d,,d,d,d,,,,d,d,d,,d,d,d,,d,d,d,,d,d,d,,d,d,d,,d,d,d,,,,d,d,d
,,,d,d,d,h,,h,d,d,d,,d,d,d,,d,d,d,,d,d,d,,d,d,d,,d,d,d,h,,h,d,d,d,,d,d,d,,d,d,d,,d,d,d,,d,d,d,,d,d,d,h,,h,d,d,d

,,,d,d,d,h,,h,d,d,d,,,,,,,,,,,,,,,,,,d,d,d,h,,h,d,d,d,,,,,,,,,,,,,,,,,,d,d,d,h,,h,d,d,d
,,,d,d,d,,,,d,d,d,,,,,,,,,,,,,,,,,,d,d,d,,,,d,d,d,,,,,,,,,,,,,,,,,,d,d,d,,,,d,d,d
,,,d,d,d,h,,h,d,d,d,,,,,,,,,,,,,,,,,,d,d,d,h,,h,d,d,d,,,,,,,,,,,,,,,,,,d,d,d,h,,h,d,d,d

,,,d,d,d,h,,h,d,d,d,,,,,,,,,,,,,,,,,,d,d,d,h,,h,d,d,d,,,,,,,,,,,,,,,,,,d,d,d,h,,h,d,d,d
,,,d,d,d,,,,d,d,d,,,,,,,,,,,,,,,,,,d,d,d,,,,d,d,d,,,,,,,,,,,,,,,,,,d,d,d,,,,d,d,d
,,,d,d,d,h,,h,d,d,d,,,,,,,,,,,,,,,,,,d,d,d,h,,h,d,d,d,,,,,,,,,,,,,,,,,,d,d,d,h,,h,d,d,d

,,,d,d,d,h,,h,d,d,d,,,,,,,,,,,,,,,,,,d,d,d,h,,h,d,d,d,,,,,,,,,,,,,,,,,,d,d,d,h,,h,d,d,d
,,,d,d,d,,,,d,d,d,,,,,,,,,,,,,,,,,,d,d,d,,,,d,d,d,,,,,,,,,,,,,,,,,,d,d,d,,,,d,d,d
,,,d,d,d,h,,h,d,d,d,,,,,,,,,,,,,,,,,,d,d,d,h,,h,d,d,d,,,,,,,,,,,,,,,,,,d,d,d,h,,h,d,d,d

,,,d,d,d,h,,h,d,d,d,,,,,,,,,,,,,,h,,,,d,d,d,h,,h,d,d,d,,,,h,,,,,,,,,,,,,,d,d,d,h,,h,d,d,d
,,,d,d,d,,,,d,d,d,,,,,,,,,,,,,,,,,,d,d,d,,,,d,d,d,,,,,,,,,,,,,,,,,,d,d,d,,,,d,d,d
,,,d,d,d,h,,h,d,d,d,,,,,,,,,,,,,,,,,,d,d,d,h,,h,d,d,d,,,,,,,,,,,,,,,,,,d,d,d,h,,h,d,d,d

,,,,,,,,,d,d,d,,d,d,d,,d,d,d,,d,d,d,,d,d,d,,,,,,,,,,,,d,d,d,,d,d,d,,d,d,d,,d,d,d,,d,d,d
,,,,,,,,,d,d,d,,d,d,d,,d,d,d,,d,d,d,,d,d,d,,,,,,,,,,,,d,d,d,,d,d,d,,d,d,d,,d,d,d,,d,d,d
,d,d,d,d,d,,,,d,d,d,,d,d,d,,d,d,d,,d,d,d,,d,d,d,,,,,,,,,,,,d,d,d,,d,d,d,,d,d,d,,d,d,d,,d,d,d,,,,d,d,d,d,d
,d,,,h,d,,,,h,,h,,h,,h,,h,,h,,h,,h,,h,,h,,,,,,,,,,,,h,,h,,h,,h,,h,,h,,h,,h,,h,,h,,,,d,,,h,d
,d,r,,r,d,,,,,,,,,,,,,,,,,,,,,,,,,,,,,,,,,,,,,,,,,,,,,,,,,,,,,,,,d,r,,r,d
,d,h,,,d,,,,h,,h,,h,,h,,h,,h,,h,,h,,h,,h,,,,,,,,,,,,h,,h,,h,,h,,h,,h,,h,,h,,h,,h,,,,d,h,,,d
,d,d,d,d,d,,,,d,d,d,,d,d,d,,d,d,d,,d,d,d,,d,d,d,,,,,,,,,,,,d,d,d,,d,d,d,,d,d,d,,d,d,d,,d,d,d,,,,d,d,d,d,d
,,,,,,,,,d,d,d,,d,d,d,,d,d,d,,d,d,d,,d,d,d,,,,,,,,,,,,d,d,d,,d,d,d,,d,d,d,,d,d,d,,d,d,d
,,,,,,,,,d,d,d,,d,d,d,,d,d,d,,d,d,d,,d,d,d,,,,,,,,,,,,d,d,d,,d,d,d,,d,d,d,,d,d,d,,d,d,d

,,,d,d,d,h,,h,d,d,d,,,,,,,,,,,,,,,,,,d,d,d,h,,h,d,d,d,,,,,,,,,,,,,,,,,,d,d,d,h,,h,d,d,d
,,,d,d,d,,,,d,d,d,,,,,,,,,,,,,,,,,,d,d,d,,,,d,d,d,,,,,,,,,,,,,,,,,,d,d,d,,,,d,d,d
,,,d,d,d,h,,h,d,d,d,,,,,,,,,,,,,,h,,,,d,d,d,h,,h,d,d,d,,,,h,,,,,,,,,,,,,,d,d,d,h,,h,d,d,d

,,,d,d,d,h,,h,d,d,d,,,,,,,,,,,,,,,,,,d,d,d,h,,h,d,d,d,,,,,,,,,,,,,,,,,,d,d,d,h,,h,d,d,d
,,,d,d,d,,,,d,d,d,,,,,,,,,,,,,,,,,,d,d,d,,,,d,d,d,,,,,,,,,,,,,,,,,,d,d,d,,,,d,d,d
,,,d,d,d,h,,h,d,d,d,,,,,,,,,,,,,,,,,,d,d,d,h,,h,d,d,d,,,,,,,,,,,,,,,,,,d,d,d,h,,h,d,d,d

,,,d,d,d,h,,h,d,d,d,,,,,,,,,,,,,,,,,,d,d,d,h,,h,d,d,d,,,,,,,,,,,,,,,,,,d,d,d,h,,h,d,d,d
,,,d,d,d,,,,d,d,d,,,,,,,,,,,,,,,,,,d,d,d,,,,d,d,d,,,,,,,,,,,,,,,,,,d,d,d,,,,d,d,d
,,,d,d,d,h,,h,d,d,d,,,,,,,,,,,,,,,,,,d,d,d,h,,h,d,d,d,,,,,,,,,,,,,,,,,,d,d,d,h,,h,d,d,d

,,,d,d,d,h,,h,d,d,d,,,,,,,,,,,,,,,,,,d,d,d,h,,h,d,d,d,,,,,,,,,,,,,,,,,,d,d,d,h,,h,d,d,d
,,,d,d,d,,,,d,d,d,,,,,,,,,,,,,,,,,,d,d,d,,,,d,d,d,,,,,,,,,,,,,,,,,,d,d,d,,,,d,d,d
,,,d,d,d,h,,h,d,d,d,,,,,,,,,,,,,,,,,,d,d,d,h,,h,d,d,d,,,,,,,,,,,,,,,,,,d,d,d,h,,h,d,d,d

,,,d,d,d,h,,h,d,d,d,,d,d,d,,d,d,d,,d,d,d,,d,d,d,,d,d,d,h,,h,d,d,d,,d,d,d,,d,d,d,,d,d,d,,d,d,d,,d,d,d,h,,h,d,d,d
,,,d,d,d,,,,d,d,d,,d,d,d,,d,d,d,,d,d,d,,d,d,d,,d,d,d,,,,d,d,d,,d,d,d,,d,d,d,,d,d,d,,d,d,d,,d,d,d,,,,d,d,d
,,,d,d,d,h,,h,d,d,d,,d,d,d,,d,d,d,,d,d,d,,d,d,d,,d,d,d,h,,h,d,d,d,,d,d,d,,d,d,d,,d,d,d,,d,d,d,,d,d,d,h,,h,d,d,d
,,,,,,,,,h,,h,,h,,h,,h,,h,,h,,h,,h,,h,,,,,,,,,,,,h,,h,,h,,h,,h,,h,,h,,h,,h,,h

,,,,,,,,,h,,h,,h,,h,,h,,h,,h,,h,,h,,h,,,,,,,,,,,,h,,h,,h,,h,,h,,h,,h,,h,,h,,h
,,,,,,,,,d,d,d,,d,d,d,,d,d,d,,d,d,d,,d,d,d,,,,d,d,d,d,d,,,,d,d,d,,d,d,d,,d,d,d,,d,d,d,,d,d,d
,,,,,,,,,d,d,d,,d,d,d,,d,d,d,,d,d,d,,d,d,d,,,,d,h,r,,d,,,,d,d,d,,d,d,d,,d,d,d,,d,d,d,,d,d,d
,,,,,,,,,d,d,d,,d,d,d,,d,d,d,,d,d,d,,d,d,d,,,,d,,,,d,,,,d,d,d,,d,d,d,,d,d,d,,d,d,d,,d,d,d
,,,,,,,,,,,,,,,,,,,,,,,,,,,,,,,d,,r,h,d
,,,,,,,,,,,,,,,,,,,,,,,,,,,,,,,d,d,d,d,d
#>

,,,,,,,,,,,,,,,,,,,,,,,,,,,,,,,d,d,d,d,d
,,,,,,,,,,,d,d,d,,d,d,d,,d,d,d,,d,d,d,,,,,,d,r,,,d,,,,,,d,d,d,,d,d,d,,d,d,d,,d,d,d
,,,,,,,,,,,d,d,d,,d,d,d,,d,d,d,,d,d,d,,,,,,d,h,,h,d,,,,,,d,d,d,,d,d,d,,d,d,d,,d,d,d
,,,,,,,,,,,d,d,d,,d,d,d,,d,d,d,,d,d,d,,,,,,d,,,r,d,,,,,,d,d,d,,d,d,d,,d,d,d,,d,d,d
,,,,,,,,,,,,d,,,,d,,,,d,,,,d,,,,,,,d,d,d,d,d,,,,,,,d,,,,d,,,,d,,,,d
,,,,,,,d,d,r,h,r,d,r,h,r,d,r,h,r,d,r,h,r,d,r,h,r,d,d,d,d,d,d,d,d,d,d,d,r,h,r,d,r,h,r,d,r,h,r,d,r,h,r,d,r,h,r,d,d
,,,,,,d,d,d,d,d,d,d,d,d,d,d,d,d,d,d,d,d,d,d,d,d,d,d,d,d,d,d,d,d,d,d,d,d,d,d,d,d,d,d,d,d,d,d,d,d,d,d,d,d,d,d,d,d,d,d
,,,,,,d,d,d,r,h,r,d,r,h,r,d,r,h,r,d,r,h,r,d,r,h,r,d,d,d,d,d,d,d,d,d,d,d,r,h,r,d,r,h,r,d,r,h,r,d,r,h,r,d,r,h,r,d,d,d
,,,,,,r,d,r,,,,,,,,d,,,,d,,,,d,,,,,,,,r,d,r,,,,,,,,d,,,,d,,,,d,,,,,,,,r,d,r
,,,,,,h,d,h,,,,,,,d,d,d,,d,d,d,,d,d,d,,,,,,,h,d,h,,,,,,,d,d,d,,d,d,d,,d,d,d,,,,,,,h,d,h
,,d,d,d,,r,d,r,,,,,,,d,d,d,,d,d,d,,d,d,d,,,d,d,d,,r,d,r,,d,d,d,,,d,d,d,,d,d,d,,d,d,d,,,,,,,r,d,r,,d,d,d
,,d,d,d,d,d,d,d,,,,,,,d,d,d,,d,d,d,,d,d,d,,,d,d,d,d,d,d,d,d,d,d,d,,,d,d,d,,d,d,d,,d,d,d,,,,,,,d,d,d,d,d,d,d
,,d,d,d,,r,d,r,,,,,,,,,,,,,,,,,,,,d,d,d,,r,d,r,,d,d,d,,,,,,,,,,,,,,,,,,,,r,d,r,,d,d,d
,,,,,,h,d,h,,,,,,,,,,,,,,,,,,,,,,,,h,d,h,,,,,,,,,,,,,,,,,,,,,,,,h,d,h
,,d,d,d,,r,d,r,,d,d,d,,,,,,,,,,,,,,,,d,d,d,,r,d,r,,d,d,d,,,,,,,,,,,,,,,,d,d,d,,r,d,r,,d,d,d
,,d,d,d,d,d,d,d,d,d,d,d,,,,,,,,,,,,,,,,d,d,d,d,d,d,d,d,d,d,d,,,,,,,,,,,,,,,,d,d,d,d,d,d,d,d,d,d,d
,,d,d,d,,r,d,r,,d,d,d,,,,,,,,,,,,,,,,d,d,d,,r,d,r,,d,d,d,,,,,,,,,,,,,,,,d,d,d,,r,d,r,,d,d,d
,,,,,,h,d,h,,,,,,,,,,,,,,,,,,,,,,,,h,d,h,,,,,,,,,,,,,,,,,,,,,,,,h,d,h
,,d,d,d,,r,d,r,,d,d,d,,,,,,,,,,,,,,,,d,d,d,,r,d,r,,d,d,d,,,,,,,,,,,,,,,,d,d,d,,r,d,r,,d,d,d
,,d,d,d,d,d,d,d,d,d,d,d,,,,,,,,,,,,,,,,d,d,d,d,d,d,d,d,d,d,d,,,,,,,,,,,,,,,,d,d,d,d,d,d,d,d,d,d,d
,,d,d,d,,r,d,r,,d,d,d,,,,,,,,,,,,,,,,d,d,d,,r,d,r,,d,d,d,,,,,,,,,,,,,,,,d,d,d,,r,d,r,,d,d,d
,,,,,,h,d,h,,,,,,,,,,,,,,,,,,,,,,,,h,d,h,,,,,,,,,,,,,,,,,,,,,,,,h,d,h
,,d,d,d,,r,d,r,,d,d,d,,,,,,,,,,,,,,,,d,d,d,,r,d,r,,d,d,d,,,,,,,,,,,,,,,,d,d,d,,r,d,r,,d,d,d
,,d,d,d,d,d,d,d,d,d,d,d,,,,,,,,,,,,,,,,d,d,d,d,d,d,d,d,d,d,d,,,,,,,,,,,,,,,,d,d,d,d,d,d,d,d,d,d,d
,,d,d,d,,r,d,r,,d,d,d,,,,,,,,,,,,,h,,,d,d,d,,r,d,r,,d,d,d,,,h,,,,,,,,,,,,,d,d,d,,r,d,r,,d,d,d
,,,,,,h,d,h,,,,,,,,,,,,,,,,,,,,,,,,h,d,h,,,,,,,,,,,,,,,,,,,,,,,,h,d,h
,,,,,,r,d,r,,,,,,,,,,,,,,,,,,,,,,,,r,d,r,,,,,,,,,,,,,,,,,,,,,,,,r,d,r
,,,,,,d,d,d,,,d,d,d,,d,d,d,,d,d,d,,d,d,d,,,,,,,d,d,d,,,,,,,d,d,d,,d,d,d,,d,d,d,,d,d,d,,,d,d,d
,,,,,,d,d,d,,,d,d,d,,d,d,d,,d,d,d,,d,d,d,,,,,,,d,d,d,,,,,,,d,d,d,,d,d,d,,d,d,d,,d,d,d,,,d,d,d
,,,,,,d,d,d,,,d,d,d,,d,d,d,,d,d,d,,d,d,d,,,,,,,d,d,d,,,,,,,d,d,d,,d,d,d,,d,d,d,,d,d,d,,,d,d,d
,d,d,d,d,d,d,d,d,,,,d,,,,d,,,,d,,,,d,,,,,,,d,d,d,d,d,,,,,,,d,,,,d,,,,d,,,,d,,,,d,d,d,d,d,d,d,d
,d,,h,r,d,d,d,d,r,h,r,d,r,h,r,d,r,h,r,d,r,h,r,d,r,h,r,d,d,d,d,d,d,d,d,d,d,d,r,h,r,d,r,h,r,d,r,h,r,d,r,h,r,d,r,h,r,d,d,d,d,,h,r,d
,d,,,,d,d,d,d,d,d,d,d,d,d,d,d,d,d,d,d,d,d,d,d,d,d,d,d,d,d,d,d,d,d,d,d,d,d,d,d,d,d,d,d,d,d,d,d,d,d,d,d,d,d,d,d,d,d,d,d,d,,,,d
,d,r,h,,d,d,d,d,r,h,r,d,r,h,r,d,r,h,r,d,r,h,r,d,r,h,r,d,d,d,d,d,d,d,d,d,d,d,r,h,r,d,r,h,r,d,r,h,r,d,r,h,r,d,r,h,r,d,d,d,d,r,h,,d
,d,d,d,d,d,d,d,d,,,,d,,,,d,,,,d,,,,d,,,,,,,d,d,d,d,d,,,,,,,d,,,,d,,,,d,,,,d,,,,d,d,d,d,d,d,d,d
,,,,,,d,d,d,,,d,d,d,,d,d,d,,d,d,d,,d,d,d,,,,,,,d,d,d,,,,,,,d,d,d,,d,d,d,,d,d,d,,d,d,d,,,d,d,d
,,,,,,d,d,d,,,d,d,d,,d,d,d,,d,d,d,,d,d,d,,,,,,,d,d,d,,,,,,,d,d,d,,d,d,d,,d,d,d,,d,d,d,,,d,d,d
,,,,,,d,d,d,,,d,d,d,,d,d,d,,d,d,d,,d,d,d,,,,,,,d,d,d,,,,,,,d,d,d,,d,d,d,,d,d,d,,d,d,d,,,d,d,d
,,,,,,r,d,r,,,,,,,,,,,,,,,,,,,,,,,,r,d,r,,,,,,,,,,,,,,,,,,,,,,,,r,d,r
,,,,,,h,d,h,,,,,,,,,,,,,,,,,,,,,,,,h,d,h,,,,,,,,,,,,,,,,,,,,,,,,h,d,h
,,d,d,d,,r,d,r,,d,d,d,,,,,,,,,,,,,h,,,d,d,d,,r,d,r,,d,d,d,,,h,,,,,,,,,,,,,d,d,d,,r,d,r,,d,d,d
,,d,d,d,d,d,d,d,d,d,d,d,,,,,,,,,,,,,,,,d,d,d,d,d,d,d,d,d,d,d,,,,,,,,,,,,,,,,d,d,d,d,d,d,d,d,d,d,d
,,d,d,d,,r,d,r,,d,d,d,,,,,,,,,,,,,,,,d,d,d,,r,d,r,,d,d,d,,,,,,,,,,,,,,,,d,d,d,,r,d,r,,d,d,d
,,,,,,h,d,h,,,,,,,,,,,,,,,,,,,,,,,,h,d,h,,,,,,,,,,,,,,,,,,,,,,,,h,d,h
,,d,d,d,,r,d,r,,d,d,d,,,,,,,,,,,,,,,,d,d,d,,r,d,r,,d,d,d,,,,,,,,,,,,,,,,d,d,d,,r,d,r,,d,d,d
,,d,d,d,d,d,d,d,d,d,d,d,,,,,,,,,,,,,,,,d,d,d,d,d,d,d,d,d,d,d,,,,,,,,,,,,,,,,d,d,d,d,d,d,d,d,d,d,d
,,d,d,d,,r,d,r,,d,d,d,,,,,,,,,,,,,,,,d,d,d,,r,d,r,,d,d,d,,,,,,,,,,,,,,,,d,d,d,,r,d,r,,d,d,d
,,,,,,h,d,h,,,,,,,,,,,,,,,,,,,,,,,,h,d,h,,,,,,,,,,,,,,,,,,,,,,,,h,d,h
,,d,d,d,,r,d,r,,d,d,d,,,,,,,,,,,,,,,,d,d,d,,r,d,r,,d,d,d,,,,,,,,,,,,,,,,d,d,d,,r,d,r,,d,d,d
,,d,d,d,d,d,d,d,d,d,d,d,,,,,,,,,,,,,,,,d,d,d,d,d,d,d,d,d,d,d,,,,,,,,,,,,,,,,d,d,d,d,d,d,d,d,d,d,d
,,d,d,d,,r,d,r,,d,d,d,,,,,,,,,,,,,,,,d,d,d,,r,d,r,,d,d,d,,,,,,,,,,,,,,,,d,d,d,,r,d,r,,d,d,d
,,,,,,h,d,h,,,,,,,,,,,,,,,,,,,,,,,,h,d,h,,,,,,,,,,,,,,,,,,,,,,,,h,d,h
,,d,d,d,,r,d,r,,,,,,,,,,,,,,,,,,,,d,d,d,,r,d,r,,d,d,d,,,,,,,,,,,,,,,,,,,,r,d,r,,d,d,d
,,d,d,d,d,d,d,d,,,,,,,d,d,d,,d,d,d,,d,d,d,,,d,d,d,d,d,d,d,d,d,d,d,,,d,d,d,,d,d,d,,d,d,d,,,,,,,d,d,d,d,d,d,d
,,d,d,d,,r,d,r,,,,,,,d,d,d,,d,d,d,,d,d,d,,,d,d,d,,r,d,r,,d,d,d,,,d,d,d,,d,d,d,,d,d,d,,,,,,,r,d,r,,d,d,d
,,,,,,h,d,h,,,,,,,d,d,d,,d,d,d,,d,d,d,,,,,,,h,d,h,,,,,,,d,d,d,,d,d,d,,d,d,d,,,,,,,h,d,h
,,,,,,r,d,r,,,,,,,,d,,,,d,,,,d,,,,,,,,r,d,r,,,,,,,,d,,,,d,,,,d,,,,,,,,r,d,r
,,,,,,d,d,d,r,h,r,d,r,h,r,d,r,h,r,d,r,h,r,d,r,h,r,d,d,d,d,d,d,d,d,d,d,d,r,h,r,d,r,h,r,d,r,h,r,d,r,h,r,d,r,h,r,d,d,d
,,,,,,d,d,d,d,d,d,d,d,d,d,d,d,d,d,d,d,d,d,d,d,d,d,d,d,d,d,d,d,d,d,d,d,d,d,d,d,d,d,d,d,d,d,d,d,d,d,d,d,d,d,d,d,d,d,d
,,,,,,,d,d,r,h,r,d,r,h,r,d,r,h,r,d,r,h,r,d,r,h,r,d,d,d,d,d,d,d,d,d,d,d,r,h,r,d,r,h,r,d,r,h,r,d,r,h,r,d,r,h,r,d,d
,,,,,,,,,,,,d,,,,d,,,,d,,,,d,,,,,,,d,d,d,d,d,,,,,,,d,,,,d,,,,d,,,,d
,,,,,,,,,,,d,d,d,,d,d,d,,d,d,d,,d,d,d,,,,,,d,r,,,d,,,,,,d,d,d,,d,d,d,,d,d,d,,d,d,d
,,,,,,,,,,,d,d,d,,d,d,d,,d,d,d,,d,d,d,,,,,,d,h,,h,d,,,,,,d,d,d,,d,d,d,,d,d,d,,d,d,d
,,,,,,,,,,,d,d,d,,d,d,d,,d,d,d,,d,d,d,,,,,,d,,,r,d,,,,,,d,d,d,,d,d,d,,d,d,d,,d,d,d
,,,,,,,,,,,,,,,,,,,,,,,,,,,,,,,d,d,d,d,d
#>

,,,,,,,,,,,,,,,,,,,,,,,,,,,,,,,d,d,d,d,d
,,,,,,,,,,,,,,,,,,,,,,,,,,,,,,,d,,,h,d
,,,,,,,,,d,d,d,,d,d,d,,d,d,d,,d,d,d,,d,d,d,,,,d,r,,r,d,,,,d,d,d,,d,d,d,,d,d,d,,d,d,d,,d,d,d
,,,,,,,,,d,d,d,,d,d,d,,d,d,d,,d,d,d,,d,d,d,,,,d,h,,,d,,,,d,d,d,,d,d,d,,d,d,d,,d,d,d,,d,d,d
,,,,,,,,,d,d,d,,d,d,d,,d,d,d,,d,d,d,,d,d,d,,,,d,d,d,d,d,,,,d,d,d,,d,d,d,,d,d,d,,d,d,d,,d,d,d
,,,,,,,,,,r,,,,r,,,,r,,,,r,,,,r,,,,,,,,,,,,,,r,,,,r,,,,r,,,,r,,,,r

,,,,,,,,,,r,,,,r,,,,r,,,,r,,,,r,,,,,,,,,,,,,,r,,,,r,,,,r,,,,r,,,,r
,,,d,d,d,,,,d,d,d,,d,d,d,,d,d,d,,d,d,d,,d,d,d,,d,d,d,,,,d,d,d,,d,d,d,,d,d,d,,d,d,d,,d,d,d,,d,d,d,,,,d,d,d
,,,d,d,d,r,,r,d,d,d,,d,d,d,,d,d,d,,d,d,d,,d,d,d,,d,d,d,r,,r,d,d,d,,d,d,d,,d,d,d,,d,d,d,,d,d,d,,d,d,d,r,,r,d,d,d
,,,d,d,d,,,,d,d,d,,d,d,d,,d,d,d,,d,d,d,,d,d,d,,d,d,d,,,,d,d,d,,d,d,d,,d,d,d,,d,d,d,,d,d,d,,d,d,d,,,,d,d,d

,,,d,d,d,,,,d,d,d,,,,,,,,,,,,,,,,,,d,d,d,,,,d,d,d,,,,,,,,,,,,,,,,,,d,d,d,,,,d,d,d
,,,d,d,d,r,,r,d,d,d,,,,,,,,,,,,,,,,,,d,d,d,r,,r,d,d,d,,,,,,,,,,,,,,,,,,d,d,d,r,,r,d,d,d
,,,d,d,d,,,,d,d,d,,,,,,,,,,,,,,,,,,d,d,d,,,,d,d,d,,,,,,,,,,,,,,,,,,d,d,d,,,,d,d,d

,,,d,d,d,,,,d,d,d,,,,,,,,,,,,,,,,,,d,d,d,,,,d,d,d,,,,,,,,,,,,,,,,,,d,d,d,,,,d,d,d
,,,d,d,d,r,,r,d,d,d,,,,,,,,,,,,,,,,,,d,d,d,r,,r,d,d,d,,,,,,,,,,,,,,,,,,d,d,d,r,,r,d,d,d
,,,d,d,d,,,,d,d,d,,,,,,,,,,,,,,,,,,d,d,d,,,,d,d,d,,,,,,,,,,,,,,,,,,d,d,d,,,,d,d,d

,,,d,d,d,,,,d,d,d,,,,,,,,,,,,,,,,,,d,d,d,,,,d,d,d,,,,,,,,,,,,,,,,,,d,d,d,,,,d,d,d
,,,d,d,d,r,,r,d,d,d,,,,,,,,,,,,,,,,,,d,d,d,r,,r,d,d,d,,,,,,,,,,,,,,,,,,d,d,d,r,,r,d,d,d
,,,d,d,d,,,,d,d,d,,,,,,,,,,,,,,,,,,d,d,d,,,,d,d,d,,,,,,,,,,,,,,,,,,d,d,d,,,,d,d,d

,,,d,d,d,,,,d,d,d,,,,,,,,,,,,,,h,,,,d,d,d,,,,d,d,d,,,,h,,,,,,,,,,,,,,d,d,d,,,,d,d,d
,,,d,d,d,r,,r,d,d,d,,,,,,,,,,,,,,,,,,d,d,d,r,,r,d,d,d,,,,,,,,,,,,,,,,,,d,d,d,r,,r,d,d,d
,,,d,d,d,,,,d,d,d,,,,,,,,,,,,,,,,,,d,d,d,,,,d,d,d,,,,,,,,,,,,,,,,,,d,d,d,,,,d,d,d

,,,,,,,,,d,d,d,,d,d,d,,d,d,d,,d,d,d,,d,d,d,,,,,,,,,,,,d,d,d,,d,d,d,,d,d,d,,d,d,d,,d,d,d
,,,,,,,,,d,d,d,,d,d,d,,d,d,d,,d,d,d,,d,d,d,,,,,,,,,,,,d,d,d,,d,d,d,,d,d,d,,d,d,d,,d,d,d
,d,d,d,d,d,,,,d,d,d,,d,d,d,,d,d,d,,d,d,d,,d,d,d,,,,,,,,,,,,d,d,d,,d,d,d,,d,d,d,,d,d,d,,d,d,d,,,,d,d,d,d,d
,d,h,r,,d,,,,,r,,,,r,,,,r,,,,r,,,,r,,,,,,,,,,,,,,r,,,,r,,,,r,,,,r,,,,r,,,,,d,h,r,,d
,d,,,,d,,,,,,,,,,,,,,,,,,,,,,,,,,,,,,,,,,,,,,,,,,,,,,,,,,,,,,,,d,,,,d
,d,,r,h,d,,,,,r,,,,r,,,,r,,,,r,,,,r,,,,,,,,,,,,,,r,,,,r,,,,r,,,,r,,,,r,,,,,d,,r,h,d
,d,d,d,d,d,,,,d,d,d,,d,d,d,,d,d,d,,d,d,d,,d,d,d,,,,,,,,,,,,d,d,d,,d,d,d,,d,d,d,,d,d,d,,d,d,d,,,,d,d,d,d,d
,,,,,,,,,d,d,d,,d,d,d,,d,d,d,,d,d,d,,d,d,d,,,,,,,,,,,,d,d,d,,d,d,d,,d,d,d,,d,d,d,,d,d,d
,,,,,,,,,d,d,d,,d,d,d,,d,d,d,,d,d,d,,d,d,d,,,,,,,,,,,,d,d,d,,d,d,d,,d,d,d,,d,d,d,,d,d,d

,,,d,d,d,,,,d,d,d,,,,,,,,,,,,,,,,,,d,d,d,,,,d,d,d,,,,,,,,,,,,,,,,,,d,d,d,,,,d,d,d
,,,d,d,d,r,,r,d,d,d,,,,,,,,,,,,,,,,,,d,d,d,r,,r,d,d,d,,,,,,,,,,,,,,,,,,d,d,d,r,,r,d,d,d
,,,d,d,d,,,,d,d,d,,,,,,,,,,,,,,h,,,,d,d,d,,,,d,d,d,,,,h,,,,,,,,,,,,,,d,d,d,,,,d,d,d

,,,d,d,d,,,,d,d,d,,,,,,,,,,,,,,,,,,d,d,d,,,,d,d,d,,,,,,,,,,,,,,,,,,d,d,d,,,,d,d,d
,,,d,d,d,r,,r,d,d,d,,,,,,,,,,,,,,,,,,d,d,d,r,,r,d,d,d,,,,,,,,,,,,,,,,,,d,d,d,r,,r,d,d,d
,,,d,d,d,,,,d,d,d,,,,,,,,,,,,,,,,,,d,d,d,,,,d,d,d,,,,,,,,,,,,,,,,,,d,d,d,,,,d,d,d

,,,d,d,d,,,,d,d,d,,,,,,,,,,,,,,,,,,d,d,d,,,,d,d,d,,,,,,,,,,,,,,,,,,d,d,d,,,,d,d,d
,,,d,d,d,r,,r,d,d,d,,,,,,,,,,,,,,,,,,d,d,d,r,,r,d,d,d,,,,,,,,,,,,,,,,,,d,d,d,r,,r,d,d,d
,,,d,d,d,,,,d,d,d,,,,,,,,,,,,,,,,,,d,d,d,,,,d,d,d,,,,,,,,,,,,,,,,,,d,d,d,,,,d,d,d

,,,d,d,d,,,,d,d,d,,,,,,,,,,,,,,,,,,d,d,d,,,,d,d,d,,,,,,,,,,,,,,,,,,d,d,d,,,,d,d,d
,,,d,d,d,r,,r,d,d,d,,,,,,,,,,,,,,,,,,d,d,d,r,,r,d,d,d,,,,,,,,,,,,,,,,,,d,d,d,r,,r,d,d,d
,,,d,d,d,,,,d,d,d,,,,,,,,,,,,,,,,,,d,d,d,,,,d,d,d,,,,,,,,,,,,,,,,,,d,d,d,,,,d,d,d

,,,d,d,d,,,,d,d,d,,d,d,d,,d,d,d,,d,d,d,,d,d,d,,d,d,d,,,,d,d,d,,d,d,d,,d,d,d,,d,d,d,,d,d,d,,d,d,d,,,,d,d,d
,,,d,d,d,r,,r,d,d,d,,d,d,d,,d,d,d,,d,d,d,,d,d,d,,d,d,d,r,,r,d,d,d,,d,d,d,,d,d,d,,d,d,d,,d,d,d,,d,d,d,r,,r,d,d,d
,,,d,d,d,,,,d,d,d,,d,d,d,,d,d,d,,d,d,d,,d,d,d,,d,d,d,,,,d,d,d,,d,d,d,,d,d,d,,d,d,d,,d,d,d,,d,d,d,,,,d,d,d
,,,,,,,,,,r,,,,r,,,,r,,,,r,,,,r,,,,,,,,,,,,,,r,,,,r,,,,r,,,,r,,,,r

,,,,,,,,,,r,,,,r,,,,r,,,,r,,,,r,,,,,,,,,,,,,,r,,,,r,,,,r,,,,r,,,,r
,,,,,,,,,d,d,d,,d,d,d,,d,d,d,,d,d,d,,d,d,d,,,,d,d,d,d,d,,,,d,d,d,,d,d,d,,d,d,d,,d,d,d,,d,d,d
,,,,,,,,,d,d,d,,d,d,d,,d,d,d,,d,d,d,,d,d,d,,,,d,,,h,d,,,,d,d,d,,d,d,d,,d,d,d,,d,d,d,,d,d,d
,,,,,,,,,d,d,d,,d,d,d,,d,d,d,,d,d,d,,d,d,d,,,,d,r,,r,d,,,,d,d,d,,d,d,d,,d,d,d,,d,d,d,,d,d,d
,,,,,,,,,,,,,,,,,,,,,,,,,,,,,,,d,h,,,d
,,,,,,,,,,,,,,,,,,,,,,,,,,,,,,,d,d,d,d,d
#build label(construct) start(34;34;center)

























































,,,,,,,,,,,,,,,,,,,,,,,,,,,,,,,,,,,,,,,,,,,,,,,,,,,,,,,,,,,,,,,,Cw
,,,,,,,,,,,,,,,,,,,,,,,,,,,,,,,,,,,,,,,,,,,,,,,,,,,,,,,,,,,,Cw,Cw,Cw,Cw,Cw
,,,,,,,,,,,,,,,,,,,,,,,,,,,,,,,,,,,,,,,,,,,,,,,,,,,,,,,,,,Cw



,,,,,,,,,,,,,,,,,,,,,,,,,,,,,,,,,,,,,,,,,,,,,,,,,,,,,,,,,,Cw
#>
























,,,,,,,,,,,,,,,,,,,,,,,,,,,Cw
,,,,,,,,,,,,,,,,,,,,,,,,,,,Cw
,,,,,,,,,,,,,,,,,,,,,,,,,,,Cw,Cw,Cw
,,,,,,,,,,,,,,,,,,,,,,,,Cw,Cw,Cw,Cw,Cw,Cw
,,,,,,,,,,,,,,,,,,,,,,,,,,Cw,Cw,Cw,Cw
,,,,,,,,,,,,,,,,,,,,,,,,,,Cw,Cw,Cw

,,,,,,,,,,,,,,,,,,,,,,,Cw,,Cw











,,,,,,,,,,,,,,,,,,,,,,,,,,,,,,,Cw,,,,Cw
#build label(build) start(34;34;center)



,,,,,,,,,f,b,h,,f,b,h,,f,b,h,,f,b,h,,f,b,h,,,,,,,,,,,,f,b,h,,f,b,h,,f,b,h,,f,b,h,,f,b,h





,,,h,,,,,,,,h,,,,,,,,,,,,,,,,,,h,,,,,,,,h,,,,,,,,,,,,,,,,,,h,,,,,,,,h
,,,b,,,,,,,,b,,,,,,,,,,,,,,,,,,b,,,,,,,,b,,,,,,,,,,,,,,,,,,b,,,,,,,,b
,,,f,,,,,,,,f,,f,b,h,,f,b,h,,f,b,h,,f,b,h,,f,,,,,,,,f,,f,b,h,,f,b,h,,f,b,h,,f,b,h,,f,,,,,,,,f

,,,h,,,,,,,,h,,,,,,,,,,,,,,,,,,h,,,,,,,,h,,,,,,,,,,,,,,,,,,h,,,,,,,,h
,,,b,,,,,,,,b,,,,,,,,,,,,,,,,,,b,,,,,,,,b,,,,,,,,,,,,,,,,,,b,,,,,,,,b
,,,f,,,,,,,,f,,,,,,,,,,,,,,,,,,f,,,,,,,,f,,,,,,,,,,,,,,,,,,f,,,,,,,,f

,,,h,,,,,,,,h,,,,,,,,,,,,,,,,,,h,,,,,,,,h,,,,,,,,,,,,,,,,,,h,,,,,,,,h
,,,b,,,,,,,,b,,,,,,,,,,,,,,,,,,b,,,,,,,,b,,,,,,,,,,,,,,,,,,b,,,,,,,,b
,,,f,,,,,,,,f,,,,,,,,,,,,,,,,,,f,,,,,,,,f,,,,,,,,,,,,,,,,,,f,,,,,,,,f

,,,h,,,,,,,,h,,,,,,,,,,,,,,,,,,h,,,,,,,,h,,,,,,,,,,,,,,,,,,h,,,,,,,,h
,,,b,,,,,,,,b,,,,,,,,,,,,,,,,,,b,,,,,,,,b,,,,,,,,,,,,,,,,,,b,,,,,,,,b
,,,f,,,,,,,,f,,,,,,,,,,,,,,,,,,f,,,,,,,,f,,,,,,,,,,,,,,,,,,f,,,,,,,,f

,,,h,,,,,,,,h,,,,,,,,,,,,,,,,,,h,,,,,,,,h,,,,,,,,,,,,,,,,,,h,,,,,,,,h
,,,b,,,,,,,,b,,,,,,,,,,,,,,,,,,b,,,,,,,,b,,,,,,,,,,,,,,,,,,b,,,,,,,,b
,,,f,,,,,,,,f,,,,,,,,,,,,,,,,,,f,,,,,,,,f,,,,,,,,,,,,,,,,,,f,,,,,,,,f

,,,,,,,,,f,b,h,,f,b,h,,f,b,h,,f,b,h,,f,b,h,,,,,,,,,,,,f,b,h,,f,b,h,,f,b,h,,f,b,h,,f,b,h







,,,,,,,,,f,b,h,,f,b,h,,f,b,h,,f,b,h,,f,b,h,,,,,,,,,,,,f,b,h,,f,b,h,,f,b,h,,f,b,h,,f,b,h

,,,h,,,,,,,,h,,,,,,,,,,,,,,,,,,h,,,,,,,,h,,,,,,,,,,,,,,,,,,h,,,,,,,,h
,,,b,,,,,,,,b,,,,,,,,,,,,,,,,,,b,,,,,,,,b,,,,,,,,,,,,,,,,,,b,,,,,,,,b
,,,f,,,,,,,,f,,,,,,,,,,,,,,,,,,f,,,,,,,,f,,,,,,,,,,,,,,,,,,f,,,,,,,,f

,,,h,,,,,,,,h,,,,,,,,,,,,,,,,,,h,,,,,,,,h,,,,,,,,,,,,,,,,,,h,,,,,,,,h
,,,b,,,,,,,,b,,,,,,,,,,,,,,,,,,b,,,,,,,,b,,,,,,,,,,,,,,,,,,b,,,,,,,,b
,,,f,,,,,,,,f,,,,,,,,,,,,,,,,,,f,,,,,,,,f,,,,,,,,,,,,,,,,,,f,,,,,,,,f

,,,h,,,,,,,,h,,,,,,,,,,,,,,,,,,h,,,,,,,,h,,,,,,,,,,,,,,,,,,h,,,,,,,,h
,,,b,,,,,,,,b,,,,,,,,,,,,,,,,,,b,,,,,,,,b,,,,,,,,,,,,,,,,,,b,,,,,,,,b
,,,f,,,,,,,,f,,,,,,,,,,,,,,,,,,f,,,,,,,,f,,,,,,,,,,,,,,,,,,f,,,,,,,,f

,,,h,,,,,,,,h,,,,,,,,,,,,,,,,,,h,,,,,,,,h,,,,,,,,,,,,,,,,,,h,,,,,,,,h
,,,b,,,,,,,,b,,,,,,,,,,,,,,,,,,b,,,,,,,,b,,,,,,,,,,,,,,,,,,b,,,,,,,,b
,,,f,,,,,,,,f,,,,,,,,,,,,,,,,,,f,,,,,,,,f,,,,,,,,,,,,,,,,,,f,,,,,,,,f

,,,h,,,,,,,,h,,f,b,h,,f,b,h,,f,b,h,,f,b,h,,h,,,,,,,,h,,f,b,h,,f,b,h,,f,b,h,,f,b,h,,h,,,,,,,,h
,,,b,,,,,,,,b,,,,,,,,,,,,,,,,,,b,,,,,,,,b,,,,,,,,,,,,,,,,,,b,,,,,,,,b
,,,f,,,,,,,,f,,,,,,,,,,,,,,,,,,f,,,,,,,,f,,,,,,,,,,,,,,,,,,f,,,,,,,,f





,,,,,,,,,f,b,h,,f,b,h,,f,b,h,,f,b,h,,f,b,h,,,,,,,,,,,,f,b,h,,f,b,h,,f,b,h,,f,b,h,,f,b,h
#>


,,,,,,,,,,,f,b,h,,f,b,h,,f,b,h,,f,b,h,,,,,,,,,,,,,,,,f,b,h,,f,b,h,,f,b,h,,f,b,h


,,,,,,,,,,,,d,,,,d,,,,d,,,,d,,,,,,,,,,,,,,,,,,d,,,,d,,,,d,,,,d



,,,,,,,,,,,,,,,,d,,,,d,,,,d,,,,,,,,,,,,,,,,,,d,,,,d,,,,d

,,h,,,,,,,,,,,,,,,,,,,,,,,,,,h,,,,,,,,,,h,,,,,,,,,,,,,,,,,,,,,,,,,,h
,,b,,,d,,,,,,,,,,f,b,h,,f,b,h,,f,b,h,,,b,,,d,,,,d,,,b,,,f,b,h,,f,b,h,,f,b,h,,,,,,,,,,d,,,b
,,f,,,,,,,,,,,,,,,,,,,,,,,,,,f,,,,,,,,,,f,,,,,,,,,,,,,,,,,,,,,,,,,,f

,,h,,,,,,,,,,h,,,,,,,,,,,,,,,,h,,,,,,,,,,h,,,,,,,,,,,,,,,,h,,,,,,,,,,h
,,b,,,d,,,,d,,,b,,,,,,,,,,,,,,,,b,,,d,,,,d,,,b,,,,,,,,,,,,,,,,b,,,d,,,,d,,,b
,,f,,,,,,,,,,f,,,,,,,,,,,,,,,,f,,,,,,,,,,f,,,,,,,,,,,,,,,,f,,,,,,,,,,f

,,h,,,,,,,,,,h,,,,,,,,,,,,,,,,h,,,,,,,,,,h,,,,,,,,,,,,,,,,h,,,,,,,,,,h
,,b,,,d,,,,d,,,b,,,,,,,,,,,,,,,,b,,,d,,,,d,,,b,,,,,,,,,,,,,,,,b,,,d,,,,d,,,b
,,f,,,,,,,,,,f,,,,,,,,,,,,,,,,f,,,,,,,,,,f,,,,,,,,,,,,,,,,f,,,,,,,,,,f

,,h,,,,,,,,,,h,,,,,,,,,,,,,,,,h,,,,,,,,,,h,,,,,,,,,,,,,,,,h,,,,,,,,,,h
,,b,,,d,,,,d,,,b,,,,,,,,,,,,,,,,b,,,d,,,,d,,,b,,,,,,,,,,,,,,,,b,,,d,,,,d,,,b
,,f,,,,,,,,,,f,,,,,,,,,,,,,,,,f,,,,,,,,,,f,,,,,,,,,,,,,,,,f,,,,,,,,,,f


,,,,,,,,,,,f,b,h,,f,b,h,,f,b,h,,f,b,h,,,,,,,,,,,,,,,,f,b,h,,f,b,h,,f,b,h,,f,b,h


,,,,,,,,,,,,d,,,,d,,,,d,,,,d,,,,,,,,,,,,,,,,,,d,,,,d,,,,d,,,,d



,,,,,,,,,,,,d,,,,d,,,,d,,,,d,,,,,,,,,,,,,,,,,,d,,,,d,,,,d,,,,d


,,,,,,,,,,,f,b,h,,f,b,h,,f,b,h,,f,b,h,,,,,,,,,,,,,,,,f,b,h,,f,b,h,,f,b,h,,f,b,h


,,h,,,,,,,,,,h,,,,,,,,,,,,,,,,h,,,,,,,,,,h,,,,,,,,,,,,,,,,h,,,,,,,,,,h
,,b,,,d,,,,d,,,b,,,,,,,,,,,,,,,,b,,,d,,,,d,,,b,,,,,,,,,,,,,,,,b,,,d,,,,d,,,b
,,f,,,,,,,,,,f,,,,,,,,,,,,,,,,f,,,,,,,,,,f,,,,,,,,,,,,,,,,f,,,,,,,,,,f

,,h,,,,,,,,,,h,,,,,,,,,,,,,,,,h,,,,,,,,,,h,,,,,,,,,,,,,,,,h,,,,,,,,,,h
,,b,,,d,,,,d,,,b,,,,,,,,,,,,,,,,b,,,d,,,,d,,,b,,,,,,,,,,,,,,,,b,,,d,,,,d,,,b
,,f,,,,,,,,,,f,,,,,,,,,,,,,,,,f,,,,,,,,,,f,,,,,,,,,,,,,,,,f,,,,,,,,,,f

,,h,,,,,,,,,,h,,,,,,,,,,,,,,,,h,,,,,,,,,,h,,,,,,,,,,,,,,,,h,,,,,,,,,,h
,,b,,,d,,,,d,,,b,,,,,,,,,,,,,,,,b,,,d,,,,d,,,b,,,,,,,,,,,,,,,,b,,,d,,,,d,,,b
,,f,,,,,,,,,,f,,,,,,,,,,,,,,,,f,,,,,,,,,,f,,,,,,,,,,,,,,,,f,,,,,,,,,,f

,,h,,,,,,,,,,,,,,,,,,,,,,,,,,h,,,,,,,,,,h,,,,,,,,,,,,,,,,,,,,,,,,,,h
,,b,,,d,,,,,,,,,,f,b,h,,f,b,h,,f,b,h,,,b,,,d,,,,d,,,b,,,f,b,h,,f,b,h,,f,b,h,,,,,,,,,,d,,,b
,,f,,,,,,,,,,,,,,,,,,,,,,,,,,f,,,,,,,,,,f,,,,,,,,,,,,,,,,,,,,,,,,,,f

,,,,,,,,,,,,,,,,d,,,,d,,,,d,,,,,,,,,,,,,,,,,,d,,,,d,,,,d



,,,,,,,,,,,,d,,,,d,,,,d,,,,d,,,,,,,,,,,,,,,,,,d,,,,d,,,,d,,,,d


,,,,,,,,,,,f,b,h,,f,b,h,,f,b,h,,f,b,h,,,,,,,,,,,,,,,,f,b,h,,f,b,h,,f,b,h,,f,b,h
#>



,,,,,,,,,h,b,f,,h,b,f,,h,b,f,,h,b,f,,h,b,f,,,,,,,,,,,,h,b,f,,h,b,f,,h,b,f,,h,b,f,,h,b,f





,,,h,,,,,,,,,,,,,,,,,,,,,,,,,,h,,,,,,,,h,,,,,,,,,,,,,,,,,,,,,,,,,,h
,,,b,,,,,,,,,,,,,,,,,,,,,,,,,,b,,,,,,,,b,,,,,,,,,,,,,,,,,,,,,,,,,,b
,,,f,,,,,,h,b,f,,h,b,f,,h,b,f,,h,b,f,,h,b,f,,f,,,,,,,,f,,h,b,f,,h,b,f,,h,b,f,,h,b,f,,h,b,f,,,,,,f

,,,h,,,,,,,,h,,,,,,,,,,,,,,,,,,h,,,,,,,,h,,,,,,,,,,,,,,,,,,h,,,,,,,,h
,,,b,,,,,,,,b,,,,,,,,,,,,,,,,,,b,,,,,,,,b,,,,,,,,,,,,,,,,,,b,,,,,,,,b
,,,f,,,,,,,,f,,,,,,,,,,,,,,,,,,f,,,,,,,,f,,,,,,,,,,,,,,,,,,f,,,,,,,,f

,,,h,,,,,,,,h,,,,,,,,,,,,,,,,,,h,,,,,,,,h,,,,,,,,,,,,,,,,,,h,,,,,,,,h
,,,b,,,,,,,,b,,,,,,,,,,,,,,,,,,b,,,,,,,,b,,,,,,,,,,,,,,,,,,b,,,,,,,,b
,,,f,,,,,,,,f,,,,,,,,,,,,,,,,,,f,,,,,,,,f,,,,,,,,,,,,,,,,,,f,,,,,,,,f

,,,h,,,,,,,,h,,,,,,,,,,,,,,,,,,h,,,,,,,,h,,,,,,,,,,,,,,,,,,h,,,,,,,,h
,,,b,,,,,,,,b,,,,,,,,,,,,,,,,,,b,,,,,,,,b,,,,,,,,,,,,,,,,,,b,,,,,,,,b
,,,f,,,,,,,,f,,,,,,,,,,,,,,,,,,f,,,,,,,,f,,,,,,,,,,,,,,,,,,f,,,,,,,,f

,,,h,,,,,,,,h,,,,,,,,,,,,,,,,,,h,,,,,,,,h,,,,,,,,,,,,,,,,,,h,,,,,,,,h
,,,b,,,,,,,,b,,,,,,,,,,,,,,,,,,b,,,,,,,,b,,,,,,,,,,,,,,,,,,b,,,,,,,,b
,,,f,,,,,,,,f,,,,,,,,,,,,,,,,,,f,,,,,,,,f,,,,,,,,,,,,,,,,,,f,,,,,,,,f

,,,,,,,,,h,b,f,,h,b,f,,h,b,f,,h,b,f,,h,b,f,,,,,,,,,,,,h,b,f,,h,b,f,,h,b,f,,h,b,f,,h,b,f







,,,,,,,,,h,b,f,,h,b,f,,h,b,f,,h,b,f,,h,b,f,,,,,,,,,,,,h,b,f,,h,b,f,,h,b,f,,h,b,f,,h,b,f

,,,h,,,,,,,,h,,,,,,,,,,,,,,,,,,h,,,,,,,,h,,,,,,,,,,,,,,,,,,h,,,,,,,,h
,,,b,,,,,,,,b,,,,,,,,,,,,,,,,,,b,,,,,,,,b,,,,,,,,,,,,,,,,,,b,,,,,,,,b
,,,f,,,,,,,,f,,,,,,,,,,,,,,,,,,f,,,,,,,,f,,,,,,,,,,,,,,,,,,f,,,,,,,,f

,,,h,,,,,,,,h,,,,,,,,,,,,,,,,,,h,,,,,,,,h,,,,,,,,,,,,,,,,,,h,,,,,,,,h
,,,b,,,,,,,,b,,,,,,,,,,,,,,,,,,b,,,,,,,,b,,,,,,,,,,,,,,,,,,b,,,,,,,,b
,,,f,,,,,,,,f,,,,,,,,,,,,,,,,,,f,,,,,,,,f,,,,,,,,,,,,,,,,,,f,,,,,,,,f

,,,h,,,,,,,,h,,,,,,,,,,,,,,,,,,h,,,,,,,,h,,,,,,,,,,,,,,,,,,h,,,,,,,,h
,,,b,,,,,,,,b,,,,,,,,,,,,,,,,,,b,,,,,,,,b,,,,,,,,,,,,,,,,,,b,,,,,,,,b
,,,f,,,,,,,,f,,,,,,,,,,,,,,,,,,f,,,,,,,,f,,,,,,,,,,,,,,,,,,f,,,,,,,,f

,,,h,,,,,,,,h,,,,,,,,,,,,,,,,,,h,,,,,,,,h,,,,,,,,,,,,,,,,,,h,,,,,,,,h
,,,b,,,,,,,,b,,,,,,,,,,,,,,,,,,b,,,,,,,,b,,,,,,,,,,,,,,,,,,b,,,,,,,,b
,,,f,,,,,,,,f,,,,,,,,,,,,,,,,,,f,,,,,,,,f,,,,,,,,,,,,,,,,,,f,,,,,,,,f

,,,h,,,,,,h,b,f,,h,b,f,,h,b,f,,h,b,f,,h,b,f,,h,,,,,,,,h,,h,b,f,,h,b,f,,h,b,f,,h,b,f,,h,b,f,,,,,,h
,,,b,,,,,,,,,,,,,,,,,,,,,,,,,,b,,,,,,,,b,,,,,,,,,,,,,,,,,,,,,,,,,,b
,,,f,,,,,,,,,,,,,,,,,,,,,,,,,,f,,,,,,,,f,,,,,,,,,,,,,,,,,,,,,,,,,,f





,,,,,,,,,h,b,f,,h,b,f,,h,b,f,,h,b,f,,h,b,f,,,,,,,,,,,,h,b,f,,h,b,f,,h,b,f,,h,b,f,,h,b,f
#zone label(zone) start(34;34;center)


,,,,,,,,b(5x5),,,,b(5x5),,,,b(5x5),,,,b(5x5),,,,b(5x5),,,,,,,,,,,,,,b(5x5),,,,b(5x5),,,,b(5x5),,,,b(5x5),,,,b(5x5)





,,b(5x5),,,,,,b(5x5),,,,b(5x5),,,,b(5x5),,,,b(5x5),,,,b(5x5),,,,b(5x5),,,,,,b(5x5),,,,b(5x5),,,,b(5x5),,,,b(5x5),,,,b(5x5),,,,b(5x5),,,,,,b(5x5)



,,b(5x5),,,,,,b(5x5),,,,,,,,,,,,,,,,,,,,b(5x5),,,,,,b(5x5),,,,,,,,,,,,,,,,,,,,b(5x5),,,,,,b(5x5)



,,b(5x5),,,,,,b(5x5),,,,,,,,,,,,,,,,,,,,b(5x5),,,,,,b(5x5),,,,,,,,,,,,,,,,,,,,b(5x5),,,,,,b(5x5)



,,b(5x5),,,,,,b(5x5),,,,,,,,,,,,,,,,,,,,b(5x5),,,,,,b(5x5),,,,,,,,,,,,,,,,,,,,b(5x5),,,,,,b(5x5)



,,b(5x5),,,,,,b(5x5),,,,,,,,,,,,,,,,,,,,b(5x5),,,,,,b(5x5),,,,,,,,,,,,,,,,,,,,b(5x5),,,,,,b(5x5)



,,,,,,,,b(5x5),,,,b(5x5),,,,b(5x5),,,,b(5x5),,,,b(5x5),,,,,,,,,,,,,,b(5x5),,,,b(5x5),,,,b(5x5),,,,b(5x5),,,,b(5x5)





,,,,,,,,b(5x5),,,,b(5x5),,,,b(5x5),,,,b(5x5),,,,b(5x5),,,,,,,,,,,,,,b(5x5),,,,b(5x5),,,,b(5x5),,,,b(5x5),,,,b(5x5)



,,b(5x5),,,,,,b(5x5),,,,,,,,,,,,,,,,,,,,b(5x5),,,,,,b(5x5),,,,,,,,,,,,,,,,,,,,b(5x5),,,,,,b(5x5)



,,b(5x5),,,,,,b(5x5),,,,,,,,,,,,,,,,,,,,b(5x5),,,,,,b(5x5),,,,,,,,,,,,,,,,,,,,b(5x5),,,,,,b(5x5)



,,b(5x5),,,,,,b(5x5),,,,,,,,,,,,,,,,,,,,b(5x5),,,,,,b(5x5),,,,,,,,,,,,,,,,,,,,b(5x5),,,,,,b(5x5)



,,b(5x5),,,,,,b(5x5),,,,,,,,,,,,,,,,,,,,b(5x5),,,,,,b(5x5),,,,,,,,,,,,,,,,,,,,b(5x5),,,,,,b(5x5)



,,b(5x5),,,,,,b(5x5),,,,b(5x5),,,,b(5x5),,,,b(5x5),,,,b(5x5),,,,b(5x5),,,,,,b(5x5),,,,b(5x5),,,,b(5x5),,,,b(5x5),,,,b(5x5),,,,b(5x5),,,,,,b(5x5)





,,,,,,,,b(5x5),,,,b(5x5),,,,b(5x5),,,,b(5x5),,,,b(5x5),,,,,,,,,,,,,,b(5x5),,,,b(5x5),,,,b(5x5),,,,b(5x5),,,,b(5x5)
#>

,,,,,,,,,,b(5x5),,,,b(5x5),,,,b(5x5),,,,b(5x5),,,,,,,,,,,,,,,,,,b(5x5),,,,b(5x5),,,,b(5x5),,,,b(5x5)







,,,,,,,,,,,,,,b(5x5),,,,b(5x5),,,,b(5x5),,,,,,,,,,,,,,,,,,b(5x5),,,,b(5x5),,,,b(5x5)
,b(5x5),,,,,,,,,,,,,,,,,,,,,,,,,,b(5x5),,,,,,,,b(5x5),,,,,,,,,,,,,,,,,,,,,,,,,,b(5x5)



,b(5x5),,,,,,,,b(5x5),,,,,,,,,,,,,,,,,,b(5x5),,,,,,,,b(5x5),,,,,,,,,,,,,,,,,,b(5x5),,,,,,,,b(5x5)



,b(5x5),,,,,,,,b(5x5),,,,,,,,,,,,,,,,,,b(5x5),,,,,,,,b(5x5),,,,,,,,,,,,,,,,,,b(5x5),,,,,,,,b(5x5)



,b(5x5),,,,,,,,b(5x5),,,,,,,,,,,,,,,,,,b(5x5),,,,,,,,b(5x5),,,,,,,,,,,,,,,,,,b(5x5),,,,,,,,b(5x5)




,,,,,,,,,,b(5x5),,,,b(5x5),,,,b(5x5),,,,b(5x5),,,,,,,,,,,,,,,,,,b(5x5),,,,b(5x5),,,,b(5x5),,,,b(5x5)







,,,,,,,,,,b(5x5),,,,b(5x5),,,,b(5x5),,,,b(5x5),,,,,,,,,,,,,,,,,,b(5x5),,,,b(5x5),,,,b(5x5),,,,b(5x5)




,b(5x5),,,,,,,,b(5x5),,,,,,,,,,,,,,,,,,b(5x5),,,,,,,,b(5x5),,,,,,,,,,,,,,,,,,b(5x5),,,,,,,,b(5x5)



,b(5x5),,,,,,,,b(5x5),,,,,,,,,,,,,,,,,,b(5x5),,,,,,,,b(5x5),,,,,,,,,,,,,,,,,,b(5x5),,,,,,,,b(5x5)



,b(5x5),,,,,,,,b(5x5),,,,,,,,,,,,,,,,,,b(5x5),,,,,,,,b(5x5),,,,,,,,,,,,,,,,,,b(5x5),,,,,,,,b(5x5)



,b(5x5),,,,,,,,,,,,,,,,,,,,,,,,,,b(5x5),,,,,,,,b(5x5),,,,,,,,,,,,,,,,,,,,,,,,,,b(5x5)
,,,,,,,,,,,,,,b(5x5),,,,b(5x5),,,,b(5x5),,,,,,,,,,,,,,,,,,b(5x5),,,,b(5x5),,,,b(5x5)







,,,,,,,,,,b(5x5),,,,b(5x5),,,,b(5x5),,,,b(5x5),,,,,,,,,,,,,,,,,,b(5x5),,,,b(5x5),,,,b(5x5),,,,b(5x5)
#>


,,,,,,,,b/zone_10113,b/zone_10113,b/zone_10113,b/zone_10113,b/zone_10113,b/zone_10115,b/zone_10115,b/zone_10115,b/zone_10115,b/zone_10117,b/zone_10117,b/zone_10117,b/zone_10117,b/zone_10119,b/zone_10119,b/zone_10119,b/zone_10111,b/zone_10111,b/zone_10111,b/zone_10111,b/zone_10111,,,,,,,,,,b/zone_10112,b/zone_10112,b/zone_10112,b/zone_10112,b/zone_10112,b/zone_10114,b/zone_10114,b/zone_10114,b/zone_10114,b/zone_10116,b/zone_10116,b/zone_10116,b/zone_10116,b/zone_10118,b/zone_10118,b/zone_10118,b/zone_10118,b/zone_10120,b/zone_10120,b/zone_10120,b/zone_10120
,,,,,,,,b/zone_10113,b/zone_10113,b/zone_10113,b/zone_10113,b/zone_10113,b/zone_10115,b/zone_10115,b/zone_10115,b/zone_10115,b/zone_10117,b/zone_10117,b/zone_10117,b/zone_10117,b/zone_10119,b/zone_10119,b/zone_10119,b/zone_10111,b/zone_10111,b/zone_10111,b/zone_10111,b/zone_10111,,,,,,,,,,b/zone_10112,b/zone_10112,b/zone_10112,b/zone_10112,b/zone_10112,b/zone_10114,b/zone_10114,b/zone_10114,b/zone_10114,b/zone_10116,b/zone_10116,b/zone_10116,b/zone_10116,b/zone_10118,b/zone_10118,b/zone_10118,b/zone_10118,b/zone_10120,b/zone_10120,b/zone_10120,b/zone_10120
,,,,,,,,b/zone_10113,b/zone_10113,b/zone_10113,b/zone_10113,b/zone_10113,b/zone_10115,b/zone_10115,b/zone_10115,b/zone_10115,b/zone_10117,b/zone_10117,b/zone_10117,b/zone_10117,b/zone_10119,b/zone_10119,b/zone_10119,b/zone_10111,b/zone_10111,b/zone_10111,b/zone_10111,b/zone_10111,,,,,,,,,,b/zone_10112,b/zone_10112,b/zone_10112,b/zone_10112,b/zone_10112,b/zone_10114,b/zone_10114,b/zone_10114,b/zone_10114,b/zone_10116,b/zone_10116,b/zone_10116,b/zone_10116,b/zone_10118,b/zone_10118,b/zone_10118,b/zone_10118,b/zone_10120,b/zone_10120,b/zone_10120,b/zone_10120
,,,,,,,,b/zone_10113,b/zone_10113,b/zone_10113,b/zone_10113,b/zone_10113,b/zone_10115,b/zone_10115,b/zone_10115,b/zone_10115,b/zone_10117,b/zone_10117,b/zone_10117,b/zone_10117,b/zone_10119,b/zone_10119,b/zone_10119,b/zone_10111,b/zone_10111,b/zone_10111,b/zone_10111,b/zone_10111,,,,,,,,,,b/zone_10112,b/zone_10112,b/zone_10112,b/zone_10112,b/zone_10112,b/zone_10114,b/zone_10114,b/zone_10114,b/zone_10114,b/zone_10116,b/zone_10116,b/zone_10116,b/zone_10116,b/zone_10118,b/zone_10118,b/zone_10118,b/zone_10118,b/zone_10120,b/zone_10120,b/zone_10120,b/zone_10120
,,,,,,,,b/zone_10113,b/zone_10113,b/zone_10113,b/zone_10113,b/zone_10113,b/zone_10115,b/zone_10115,b/zone_10115,b/zone_10115,b/zone_10117,b/zone_10117,b/zone_10117,b/zone_10117,b/zone_10119,b/zone_10119,b/zone_10119,b/zone_10111,b/zone_10111,b/zone_10111,b/zone_10111,b/zone_10111,,,,,,,,,,b/zone_10112,b/zone_10112,b/zone_10112,b/zone_10112,b/zone_10112,b/zone_10114,b/zone_10114,b/zone_10114,b/zone_10114,b/zone_10116,b/zone_10116,b/zone_10116,b/zone_10116,b/zone_10118,b/zone_10118,b/zone_10118,b/zone_10118,b/zone_10120,b/zone_10120,b/zone_10120,b/zone_10120
,,,,,,,,,b/zone_10113,b/zone_10113,b/zone_10113,,b/zone_10115,b/zone_10115,b/zone_10115,,b/zone_10117,b/zone_10117,b/zone_10117,,b/zone_10119,b/zone_10119,b/zone_10119,,b/zone_10111,b/zone_10111,b/zone_10111,,,,,,,,,,,,b/zone_10112,b/zone_10112,b/zone_10112,,b/zone_10114,b/zone_10114,b/zone_10114,,b/zone_10116,b/zone_10116,b/zone_10116,,b/zone_10118,b/zone_10118,b/zone_10118,,b/zone_10120,b/zone_10120,b/zone_10120
,,b/zone_10122,b/zone_10122,b/zone_10122,b/zone_10122,b/zone_10122,,b/zone_10131,b/zone_10131,b/zone_10131,b/zone_10131,b/zone_10131,b/zone_10132,b/zone_10132,b/zone_10132,b/zone_10132,b/zone_10133,b/zone_10133,b/zone_10133,b/zone_10133,b/zone_10134,b/zone_10134,b/zone_10134,b/zone_10125,b/zone_10125,b/zone_10125,b/zone_10125,b/zone_10124,b/zone_10124,b/zone_10124,b/zone_10124,b/zone_10124,,b/zone_10123,b/zone_10123,b/zone_10123,b/zone_10123,b/zone_10123,b/zone_10126,b/zone_10126,b/zone_10126,b/zone_10126,b/zone_10127,b/zone_10127,b/zone_10127,b/zone_10127,b/zone_10128,b/zone_10128,b/zone_10128,b/zone_10128,b/zone_10129,b/zone_10129,b/zone_10129,b/zone_10129,b/zone_10130,b/zone_10130,b/zone_10130,b/zone_10130,,b/zone_10121,b/zone_10121,b/zone_10121,b/zone_10121,b/zone_10121
,,b/zone_10122,b/zone_10122,b/zone_10122,b/zone_10122,b/zone_10122,b/zone_10122,b/zone_10131,b/zone_10131,b/zone_10131,b/zone_10131,b/zone_10131,b/zone_10132,b/zone_10132,b/zone_10132,b/zone_10132,b/zone_10133,b/zone_10133,b/zone_10133,b/zone_10133,b/zone_10134,b/zone_10134,b/zone_10134,b/zone_10125,b/zone_10125,b/zone_10125,b/zone_10125,b/zone_10124,b/zone_10124,b/zone_10124,b/zone_10124,b/zone_10124,b/zone_10123,b/zone_10123,b/zone_10123,b/zone_10123,b/zone_10123,b/zone_10123,b/zone_10126,b/zone_10126,b/zone_10126,b/zone_10126,b/zone_10127,b/zone_10127,b/zone_10127,b/zone_10127,b/zone_10128,b/zone_10128,b/zone_10128,b/zone_10128,b/zone_10129,b/zone_10129,b/zone_10129,b/zone_10129,b/zone_10130,b/zone_10130,b/zone_10130,b/zone_10130,b/zone_10121,b/zone_10121,b/zone_10121,b/zone_10121,b/zone_10121,b/zone_10121
,,b/zone_10122,b/zone_10122,b/zone_10122,b/zone_10122,b/zone_10122,b/zone_10122,b/zone_10131,b/zone_10131,b/zone_10131,b/zone_10131,b/zone_10131,b/zone_10132,b/zone_10132,b/zone_10132,b/zone_10132,b/zone_10133,b/zone_10133,b/zone_10133,b/zone_10133,b/zone_10134,b/zone_10134,b/zone_10134,b/zone_10125,b/zone_10125,b/zone_10125,b/zone_10125,b/zone_10124,b/zone_10124,b/zone_10124,b/zone_10124,b/zone_10124,b/zone_10123,b/zone_10123,b/zone_10123,b/zone_10123,b/zone_10123,b/zone_10123,b/zone_10126,b/zone_10126,b/zone_10126,b/zone_10126,b/zone_10127,b/zone_10127,b/zone_10127,b/zone_10127,b/zone_10128,b/zone_10128,b/zone_10128,b/zone_10128,b/zone_10129,b/zone_10129,b/zone_10129,b/zone_10129,b/zone_10130,b/zone_10130,b/zone_10130,b/zone_10130,b/zone_10121,b/zone_10121,b/zone_10121,b/zone_10121,b/zone_10121,b/zone_10121
,,b/zone_10122,b/zone_10122,b/zone_10122,b/zone_10122,b/zone_10122,b/zone_10122,b/zone_10131,b/zone_10131,b/zone_10131,b/zone_10131,b/zone_10131,b/zone_10132,b/zone_10132,b/zone_10132,b/zone_10132,b/zone_10133,b/zone_10133,b/zone_10133,b/zone_10133,b/zone_10134,b/zone_10134,b/zone_10134,b/zone_10125,b/zone_10125,b/zone_10125,b/zone_10125,b/zone_10124,b/zone_10124,b/zone_10124,b/zone_10124,b/zone_10124,b/zone_10123,b/zone_10123,b/zone_10123,b/zone_10123,b/zone_10123,b/zone_10123,b/zone_10126,b/zone_10126,b/zone_10126,b/zone_10126,b/zone_10127,b/zone_10127,b/zone_10127,b/zone_10127,b/zone_10128,b/zone_10128,b/zone_10128,b/zone_10128,b/zone_10129,b/zone_10129,b/zone_10129,b/zone_10129,b/zone_10130,b/zone_10130,b/zone_10130,b/zone_10130,b/zone_10121,b/zone_10121,b/zone_10121,b/zone_10121,b/zone_10121,b/zone_10121
,,b/zone_10122,b/zone_10122,b/zone_10122,b/zone_10122,b/zone_10122,,b/zone_10131,b/zone_10131,b/zone_10131,b/zone_10131,b/zone_10131,b/zone_10132,b/zone_10132,b/zone_10132,b/zone_10132,b/zone_10133,b/zone_10133,b/zone_10133,b/zone_10133,b/zone_10134,b/zone_10134,b/zone_10134,b/zone_10125,b/zone_10125,b/zone_10125,b/zone_10125,b/zone_10124,b/zone_10124,b/zone_10124,b/zone_10124,b/zone_10124,,b/zone_10123,b/zone_10123,b/zone_10123,b/zone_10123,b/zone_10123,b/zone_10126,b/zone_10126,b/zone_10126,b/zone_10126,b/zone_10127,b/zone_10127,b/zone_10127,b/zone_10127,b/zone_10128,b/zone_10128,b/zone_10128,b/zone_10128,b/zone_10129,b/zone_10129,b/zone_10129,b/zone_10129,b/zone_10130,b/zone_10130,b/zone_10130,b/zone_10130,,b/zone_10121,b/zone_10121,b/zone_10121,b/zone_10121,b/zone_10121
,,b/zone_10140,b/zone_10140,b/zone_10140,b/zone_10140,b/zone_10140,b/zone_10135,b/zone_10135,b/zone_10135,b/zone_10135,b/zone_10135,b/zone_10135,,,,,,,,,,,,,,,,b/zone_10136,b/zone_10136,b/zone_10136,b/zone_10136,b/zone_10136,b/zone_10136,b/zone_10139,b/zone_10139,b/zone_10139,b/zone_10139,b/zone_10139,,,,,,,,,,,,,,,,b/zone_10138,b/zone_10138,b/zone_10138,b/zone_10138,b/zone_10138,b/zone_10137,b/zone_10137,b/zone_10137,b/zone_10137,b/zone_10137,b/zone_10137
,,b/zone_10140,b/zone_10140,b/zone_10140,b/zone_10140,b/zone_10140,b/zone_10135,b/zone_10135,b/zone_10135,b/zone_10135,b/zone_10135,b/zone_10135,,,,,,,,,,,,,,,,b/zone_10136,b/zone_10136,b/zone_10136,b/zone_10136,b/zone_10136,b/zone_10136,b/zone_10139,b/zone_10139,b/zone_10139,b/zone_10139,b/zone_10139,,,,,,,,,,,,,,,,b/zone_10138,b/zone_10138,b/zone_10138,b/zone_10138,b/zone_10138,b/zone_10137,b/zone_10137,b/zone_10137,b/zone_10137,b/zone_10137,b/zone_10137
,,b/zone_10140,b/zone_10140,b/zone_10140,b/zone_10140,b/zone_10140,b/zone_10135,b/zone_10135,b/zone_10135,b/zone_10135,b/zone_10135,b/zone_10135,,,,,,,,,,,,,,,,b/zone_10136,b/zone_10136,b/zone_10136,b/zone_10136,b/zone_10136,b/zone_10136,b/zone_10139,b/zone_10139,b/zone_10139,b/zone_10139,b/zone_10139,,,,,,,,,,,,,,,,b/zone_10138,b/zone_10138,b/zone_10138,b/zone_10138,b/zone_10138,b/zone_10137,b/zone_10137,b/zone_10137,b/zone_10137,b/zone_10137,b/zone_10137
,,b/zone_10140,b/zone_10140,b/zone_10140,b/zone_10140,b/zone_10140,,b/zone_10135,b/zone_10135,b/zone_10135,b/zone_10135,b/zone_10135,,,,,,,,,,,,,,,,b/zone_10136,b/zone_10136,b/zone_10136,b/zone_10136,b/zone_10136,,b/zone_10139,b/zone_10139,b/zone_10139,b/zone_10139,b/zone_10139,,,,,,,,,,,,,,,,b/zone_10138,b/zone_10138,b/zone_10138,b/zone_10138,b/zone_10138,,b/zone_10137,b/zone_10137,b/zone_10137,b/zone_10137,b/zone_10137
,,b/zone_10146,b/zone_10146,b/zone_10146,b/zone_10146,b/zone_10146,b/zone_10141,b/zone_10141,b/zone_10141,b/zone_10141,b/zone_10141,b/zone_10141,,,,,,,,,,,,,,,,b/zone_10142,b/zone_10142,b/zone_10142,b/zone_10142,b/zone_10142,b/zone_10142,b/zone_10145,b/zone_10145,b/zone_10145,b/zone_10145,b/zone_10145,,,,,,,,,,,,,,,,b/zone_10144,b/zone_10144,b/zone_10144,b/zone_10144,b/zone_10144,b/zone_10143,b/zone_10143,b/zone_10143,b/zone_10143,b/zone_10143,b/zone_10143
,,b/zone_10146,b/zone_10146,b/zone_10146,b/zone_10146,b/zone_10146,b/zone_10141,b/zone_10141,b/zone_10141,b/zone_10141,b/zone_10141,b/zone_10141,,,,,,,,,,,,,,,,b/zone_10142,b/zone_10142,b/zone_10142,b/zone_10142,b/zone_10142,b/zone_10142,b/zone_10145,b/zone_10145,b/zone_10145,b/zone_10145,b/zone_10145,,,,,,,,,,,,,,,,b/zone_10144,b/zone_10144,b/zone_10144,b/zone_10144,b/zone_10144,b/zone_10143,b/zone_10143,b/zone_10143,b/zone_10143,b/zone_10143,b/zone_10143
,,b/zone_10146,b/zone_10146,b/zone_10146,b/zone_10146,b/zone_10146,b/zone_10141,b/zone_10141,b/zone_10141,b/zone_10141,b/zone_10141,b/zone_10141,,,,,,,,,,,,,,,,b/zone_10142,b/zone_10142,b/zone_10142,b/zone_10142,b/zone_10142,b/zone_10142,b/zone_10145,b/zone_10145,b/zone_10145,b/zone_10145,b/zone_10145,,,,,,,,,,,,,,,,b/zone_10144,b/zone_10144,b/zone_10144,b/zone_10144,b/zone_10144,b/zone_10143,b/zone_10143,b/zone_10143,b/zone_10143,b/zone_10143,b/zone_10143
,,b/zone_10146,b/zone_10146,b/zone_10146,b/zone_10146,b/zone_10146,,b/zone_10141,b/zone_10141,b/zone_10141,b/zone_10141,b/zone_10141,,,,,,,,,,,,,,,,b/zone_10142,b/zone_10142,b/zone_10142,b/zone_10142,b/zone_10142,,b/zone_10145,b/zone_10145,b/zone_10145,b/zone_10145,b/zone_10145,,,,,,,,,,,,,,,,b/zone_10144,b/zone_10144,b/zone_10144,b/zone_10144,b/zone_10144,,b/zone_10143,b/zone_10143,b/zone_10143,b/zone_10143,b/zone_10143
,,b/zone_10152,b/zone_10152,b/zone_10152,b/zone_10152,b/zone_10152,b/zone_10147,b/zone_10147,b/zone_10147,b/zone_10147,b/zone_10147,b/zone_10147,,,,,,,,,,,,,,,,b/zone_10148,b/zone_10148,b/zone_10148,b/zone_10148,b/zone_10148,b/zone_10148,b/zone_10151,b/zone_10151,b/zone_10151,b/zone_10151,b/zone_10151,,,,,,,,,,,,,,,,b/zone_10150,b/zone_10150,b/zone_10150,b/zone_10150,b/zone_10150,b/zone_10149,b/zone_10149,b/zone_10149,b/zone_10149,b/zone_10149,b/zone_10149
,,b/zone_10152,b/zone_10152,b/zone_10152,b/zone_10152,b/zone_10152,b/zone_10147,b/zone_10147,b/zone_10147,b/zone_10147,b/zone_10147,b/zone_10147,,,,,,,,,,,,,,,,b/zone_10148,b/zone_10148,b/zone_10148,b/zone_10148,b/zone_10148,b/zone_10148,b/zone_10151,b/zone_10151,b/zone_10151,b/zone_10151,b/zone_10151,,,,,,,,,,,,,,,,b/zone_10150,b/zone_10150,b/zone_10150,b/zone_10150,b/zone_10150,b/zone_10149,b/zone_10149,b/zone_10149,b/zone_10149,b/zone_10149,b/zone_10149
,,b/zone_10152,b/zone_10152,b/zone_10152,b/zone_10152,b/zone_10152,b/zone_10147,b/zone_10147,b/zone_10147,b/zone_10147,b/zone_10147,b/zone_10147,,,,,,,,,,,,,,,,b/zone_10148,b/zone_10148,b/zone_10148,b/zone_10148,b/zone_10148,b/zone_10148,b/zone_10151,b/zone_10151,b/zone_10151,b/zone_10151,b/zone_10151,,,,,,,,,,,,,,,,b/zone_10150,b/zone_10150,b/zone_10150,b/zone_10150,b/zone_10150,b/zone_10149,b/zone_10149,b/zone_10149,b/zone_10149,b/zone_10149,b/zone_10149
,,b/zone_10042,b/zone_10042,b/zone_10042,b/zone_10042,b/zone_10042,,b/zone_10037,b/zone_10037,b/zone_10037,b/zone_10037,b/zone_10037,,,,,,,,,,,,,,,,b/zone_10038,b/zone_10038,b/zone_10038,b/zone_10038,b/zone_10038,,b/zone_10041,b/zone_10041,b/zone_10041,b/zone_10041,b/zone_10041,,,,,,,,,,,,,,,,b/zone_10040,b/zone_10040,b/zone_10040,b/zone_10040,b/zone_10040,,b/zone_10039,b/zone_10039,b/zone_10039,b/zone_10039,b/zone_10039
,,b/zone_10042,b/zone_10042,b/zone_10042,b/zone_10042,b/zone_10042,b/zone_10037,b/zone_10037,b/zone_10037,b/zone_10037,b/zone_10037,b/zone_10037,,,,,,,,,,,,,,,,b/zone_10038,b/zone_10038,b/zone_10038,b/zone_10038,b/zone_10038,b/zone_10038,b/zone_10041,b/zone_10041,b/zone_10041,b/zone_10041,b/zone_10041,,,,,,,,,,,,,,,,b/zone_10040,b/zone_10040,b/zone_10040,b/zone_10040,b/zone_10040,b/zone_10039,b/zone_10039,b/zone_10039,b/zone_10039,b/zone_10039,b/zone_10039
,,b/zone_10042,b/zone_10042,b/zone_10042,b/zone_10042,b/zone_10042,b/zone_10037,b/zone_10037,b/zone_10037,b/zone_10037,b/zone_10037,b/zone_10037,,,,,,,,,,,,,,,,b/zone_10038,b/zone_10038,b/zone_10038,b/zone_10038,b/zone_10038,b/zone_10038,b/zone_10041,b/zone_10041,b/zone_10041,b/zone_10041,b/zone_10041,,,,,,,,,,,,,,,,b/zone_10040,b/zone_10040,b/zone_10040,b/zone_10040,b/zone_10040,b/zone_10039,b/zone_10039,b/zone_10039,b/zone_10039,b/zone_10039,b/zone_10039
,,b/zone_10042,b/zone_10042,b/zone_10042,b/zone_10042,b/zone_10042,b/zone_10037,b/zone_10037,b/zone_10037,b/zone_10037,b/zone_10037,b/zone_10037,,,,,,,,,,,,,,,,b/zone_10038,b/zone_10038,b/zone_10038,b/zone_10038,b/zone_10038,b/zone_10038,b/zone_10041,b/zone_10041,b/zone_10041,b/zone_10041,b/zone_10041,,,,,,,,,,,,,,,,b/zone_10040,b/zone_10040,b/zone_10040,b/zone_10040,b/zone_10040,b/zone_10039,b/zone_10039,b/zone_10039,b/zone_10039,b/zone_10039,b/zone_10039
,,b/zone_10042,b/zone_10042,b/zone_10042,b/zone_10042,b/zone_10042,,b/zone_10037,b/zone_10037,b/zone_10037,b/zone_10037,b/zone_10037,b/zone_10047,b/zone_10047,b/zone_10047,b/zone_10047,b/zone_10049,b/zone_10049,b/zone_10049,b/zone_10049,b/zone_10051,b/zone_10051,b/zone_10051,b/zone_10043,b/zone_10043,b/zone_10043,b/zone_10043,b/zone_10038,b/zone_10038,b/zone_10038,b/zone_10038,b/zone_10038,,b/zone_10041,b/zone_10041,b/zone_10041,b/zone_10041,b/zone_10041,b/zone_10044,b/zone_10044,b/zone_10044,b/zone_10044,b/zone_10046,b/zone_10046,b/zone_10046,b/zone_10046,b/zone_10048,b/zone_10048,b/zone_10048,b/zone_10048,b/zone_10050,b/zone_10050,b/zone_10050,b/zone_10040,b/zone_10040,b/zone_10040,b/zone_10040,b/zone_10040,,b/zone_10039,b/zone_10039,b/zone_10039,b/zone_10039,b/zone_10039
,,,,,,,,b/zone_10045,b/zone_10045,b/zone_10045,b/zone_10045,b/zone_10045,b/zone_10047,b/zone_10047,b/zone_10047,b/zone_10047,b/zone_10049,b/zone_10049,b/zone_10049,b/zone_10049,b/zone_10051,b/zone_10051,b/zone_10051,b/zone_10043,b/zone_10043,b/zone_10043,b/zone_10043,b/zone_10043,,,,,,,,,,b/zone_10044,b/zone_10044,b/zone_10044,b/zone_10044,b/zone_10044,b/zone_10046,b/zone_10046,b/zone_10046,b/zone_10046,b/zone_10048,b/zone_10048,b/zone_10048,b/zone_10048,b/zone_10050,b/zone_10050,b/zone_10050,b/zone_10050,b/zone_10052,b/zone_10052,b/zone_10052,b/zone_10052
,,,,,,,,b/zone_10045,b/zone_10045,b/zone_10045,b/zone_10045,b/zone_10045,b/zone_10047,b/zone_10047,b/zone_10047,b/zone_10047,b/zone_10049,b/zone_10049,b/zone_10049,b/zone_10049,b/zone_10051,b/zone_10051,b/zone_10051,b/zone_10043,b/zone_10043,b/zone_10043,b/zone_10043,b/zone_10043,,,,,,,,,,b/zone_10044,b/zone_10044,b/zone_10044,b/zone_10044,b/zone_10044,b/zone_10046,b/zone_10046,b/zone_10046,b/zone_10046,b/zone_10048,b/zone_10048,b/zone_10048,b/zone_10048,b/zone_10050,b/zone_10050,b/zone_10050,b/zone_10050,b/zone_10052,b/zone_10052,b/zone_10052,b/zone_10052
,,,,,,,,b/zone_10045,b/zone_10045,b/zone_10045,b/zone_10045,b/zone_10045,b/zone_10047,b/zone_10047,b/zone_10047,b/zone_10047,b/zone_10049,b/zone_10049,b/zone_10049,b/zone_10049,b/zone_10051,b/zone_10051,b/zone_10051,b/zone_10043,b/zone_10043,b/zone_10043,b/zone_10043,b/zone_10043,,,,,,,,,,b/zone_10044,b/zone_10044,b/zone_10044,b/zone_10044,b/zone_10044,b/zone_10046,b/zone_10046,b/zone_10046,b/zone_10046,b/zone_10048,b/zone_10048,b/zone_10048,b/zone_10048,b/zone_10050,b/zone_10050,b/zone_10050,b/zone_10050,b/zone_10052,b/zone_10052,b/zone_10052,b/zone_10052
,,,,,,,,b/zone_10045,b/zone_10045,b/zone_10045,b/zone_10045,b/zone_10045,b/zone_10047,b/zone_10047,b/zone_10047,b/zone_10047,b/zone_10049,b/zone_10049,b/zone_10049,b/zone_10049,b/zone_10051,b/zone_10051,b/zone_10051,b/zone_10043,b/zone_10043,b/zone_10043,b/zone_10043,b/zone_10043,,,,,,,,,,b/zone_10044,b/zone_10044,b/zone_10044,b/zone_10044,b/zone_10044,b/zone_10046,b/zone_10046,b/zone_10046,b/zone_10046,b/zone_10048,b/zone_10048,b/zone_10048,b/zone_10048,b/zone_10050,b/zone_10050,b/zone_10050,b/zone_10050,b/zone_10052,b/zone_10052,b/zone_10052,b/zone_10052
,,,,,,,,,b/zone_10045,b/zone_10045,b/zone_10045,,b/zone_10047,b/zone_10047,b/zone_10047,,b/zone_10049,b/zone_10049,b/zone_10049,,b/zone_10051,b/zone_10051,b/zone_10051,,b/zone_10043,b/zone_10043,b/zone_10043,,,,,,,,,,,,b/zone_10044,b/zone_10044,b/zone_10044,,b/zone_10046,b/zone_10046,b/zone_10046,,b/zone_10048,b/zone_10048,b/zone_10048,,b/zone_10050,b/zone_10050,b/zone_10050,,b/zone_10052,b/zone_10052,b/zone_10052
,,,,,,,,b/zone_10055,b/zone_10055,b/zone_10055,b/zone_10055,b/zone_10055,b/zone_10057,b/zone_10057,b/zone_10057,b/zone_10057,b/zone_10059,b/zone_10059,b/zone_10059,b/zone_10059,b/zone_10061,b/zone_10061,b/zone_10061,b/zone_10053,b/zone_10053,b/zone_10053,b/zone_10053,b/zone_10053,,,,,,,,,,b/zone_10054,b/zone_10054,b/zone_10054,b/zone_10054,b/zone_10054,b/zone_10056,b/zone_10056,b/zone_10056,b/zone_10056,b/zone_10058,b/zone_10058,b/zone_10058,b/zone_10058,b/zone_10060,b/zone_10060,b/zone_10060,b/zone_10060,b/zone_10062,b/zone_10062,b/zone_10062,b/zone_10062
,,,,,,,,b/zone_10055,b/zone_10055,b/zone_10055,b/zone_10055,b/zone_10055,b/zone_10057,b/zone_10057,b/zone_10057,b/zone_10057,b/zone_10059,b/zone_10059,b/zone_10059,b/zone_10059,b/zone_10061,b/zone_10061,b/zone_10061,b/zone_10053,b/zone_10053,b/zone_10053,b/zone_10053,b/zone_10053,,,,,,,,,,b/zone_10054,b/zone_10054,b/zone_10054,b/zone_10054,b/zone_10054,b/zone_10056,b/zone_10056,b/zone_10056,b/zone_10056,b/zone_10058,b/zone_10058,b/zone_10058,b/zone_10058,b/zone_10060,b/zone_10060,b/zone_10060,b/zone_10060,b/zone_10062,b/zone_10062,b/zone_10062,b/zone_10062
,,,,,,,,b/zone_10055,b/zone_10055,b/zone_10055,b/zone_10055,b/zone_10055,b/zone_10057,b/zone_10057,b/zone_10057,b/zone_10057,b/zone_10059,b/zone_10059,b/zone_10059,b/zone_10059,b/zone_10061,b/zone_10061,b/zone_10061,b/zone_10053,b/zone_10053,b/zone_10053,b/zone_10053,b/zone_10053,,,,,,,,,,b/zone_10054,b/zone_10054,b/zone_10054,b/zone_10054,b/zone_10054,b/zone_10056,b/zone_10056,b/zone_10056,b/zone_10056,b/zone_10058,b/zone_10058,b/zone_10058,b/zone_10058,b/zone_10060,b/zone_10060,b/zone_10060,b/zone_10060,b/zone_10062,b/zone_10062,b/zone_10062,b/zone_10062
,,,,,,,,b/zone_10055,b/zone_10055,b/zone_10055,b/zone_10055,b/zone_10055,b/zone_10057,b/zone_10057,b/zone_10057,b/zone_10057,b/zone_10059,b/zone_10059,b/zone_10059,b/zone_10059,b/zone_10061,b/zone_10061,b/zone_10061,b/zone_10053,b/zone_10053,b/zone_10053,b/zone_10053,b/zone_10053,,,,,,,,,,b/zone_10054,b/zone_10054,b/zone_10054,b/zone_10054,b/zone_10054,b/zone_10056,b/zone_10056,b/zone_10056,b/zone_10056,b/zone_10058,b/zone_10058,b/zone_10058,b/zone_10058,b/zone_10060,b/zone_10060,b/zone_10060,b/zone_10060,b/zone_10062,b/zone_10062,b/zone_10062,b/zone_10062
,,b/zone_10068,b/zone_10068,b/zone_10068,b/zone_10068,b/zone_10068,,b/zone_10055,b/zone_10055,b/zone_10055,b/zone_10055,b/zone_10055,b/zone_10057,b/zone_10057,b/zone_10057,b/zone_10057,b/zone_10059,b/zone_10059,b/zone_10059,b/zone_10059,b/zone_10061,b/zone_10061,b/zone_10061,b/zone_10053,b/zone_10053,b/zone_10053,b/zone_10053,b/zone_10053,b/zone_10064,b/zone_10064,b/zone_10064,b/zone_10064,,b/zone_10067,b/zone_10067,b/zone_10067,b/zone_10067,b/zone_10054,b/zone_10054,b/zone_10054,b/zone_10054,b/zone_10054,b/zone_10056,b/zone_10056,b/zone_10056,b/zone_10056,b/zone_10058,b/zone_10058,b/zone_10058,b/zone_10058,b/zone_10060,b/zone_10060,b/zone_10060,b/zone_10060,b/zone_10062,b/zone_10062,b/zone_10062,b/zone_10062,,b/zone_10065,b/zone_10065,b/zone_10065,b/zone_10065,b/zone_10065
,,b/zone_10068,b/zone_10068,b/zone_10068,b/zone_10068,b/zone_10068,b/zone_10063,b/zone_10063,b/zone_10063,b/zone_10063,b/zone_10063,b/zone_10063,,,,,,,,,,,,,,,,b/zone_10064,b/zone_10064,b/zone_10064,b/zone_10064,b/zone_10064,b/zone_10064,b/zone_10067,b/zone_10067,b/zone_10067,b/zone_10067,b/zone_10067,,,,,,,,,,,,,,,,b/zone_10066,b/zone_10066,b/zone_10066,b/zone_10066,b/zone_10066,b/zone_10065,b/zone_10065,b/zone_10065,b/zone_10065,b/zone_10065,b/zone_10065
,,b/zone_10068,b/zone_10068,b/zone_10068,b/zone_10068,b/zone_10068,b/zone_10063,b/zone_10063,b/zone_10063,b/zone_10063,b/zone_10063,b/zone_10063,,,,,,,,,,,,,,,,b/zone_10064,b/zone_10064,b/zone_10064,b/zone_10064,b/zone_10064,b/zone_10064,b/zone_10067,b/zone_10067,b/zone_10067,b/zone_10067,b/zone_10067,,,,,,,,,,,,,,,,b/zone_10066,b/zone_10066,b/zone_10066,b/zone_10066,b/zone_10066,b/zone_10065,b/zone_10065,b/zone_10065,b/zone_10065,b/zone_10065,b/zone_10065
,,b/zone_10068,b/zone_10068,b/zone_10068,b/zone_10068,b/zone_10068,b/zone_10063,b/zone_10063,b/zone_10063,b/zone_10063,b/zone_10063,b/zone_10063,,,,,,,,,,,,,,,,b/zone_10064,b/zone_10064,b/zone_10064,b/zone_10064,b/zone_10064,b/zone_10064,b/zone_10067,b/zone_10067,b/zone_10067,b/zone_10067,b/zone_10067,,,,,,,,,,,,,,,,b/zone_10066,b/zone_10066,b/zone_10066,b/zone_10066,b/zone_10066,b/zone_10065,b/zone_10065,b/zone_10065,b/zone_10065,b/zone_10065,b/zone_10065
,,b/zone_10068,b/zone_10068,b/zone_10068,b/zone_10068,b/zone_10068,,b/zone_10063,b/zone_10063,b/zone_10063,b/zone_10063,b/zone_10063,,,,,,,,,,,,,,,,b/zone_10064,b/zone_10064,b/zone_10064,b/zone_10064,b/zone_10064,,b/zone_10067,b/zone_10067,b/zone_10067,b/zone_10067,b/zone_10067,,,,,,,,,,,,,,,,b/zone_10066,b/zone_10066,b/zone_10066,b/zone_10066,b/zone_10066,,b/zone_10065,b/zone_10065,b/zone_10065,b/zone_10065,b/zone_10065
,,b/zone_10074,b/zone_10074,b/zone_10074,b/zone_10074,b/zone_10074,b/zone_10069,b/zone_10069,b/zone_10069,b/zone_10069,b/zone_10069,b/zone_10069,,,,,,,,,,,,,,,,b/zone_10070,b/zone_10070,b/zone_10070,b/zone_10070,b/zone_10070,b/zone_10070,b/zone_10073,b/zone_10073,b/zone_10073,b/zone_10073,b/zone_10073,,,,,,,,,,,,,,,,b/zone_10072,b/zone_10072,b/zone_10072,b/zone_10072,b/zone_10072,b/zone_10071,b/zone_10071,b/zone_10071,b/zone_10071,b/zone_10071,b/zone_10071
,,b/zone_10074,b/zone_10074,b/zone_10074,b/zone_10074,b/zone_10074,b/zone_10069,b/zone_10069,b/zone_10069,b/zone_10069,b/zone_10069,b/zone_10069,,,,,,,,,,,,,,,,b/zone_10070,b/zone_10070,b/zone_10070,b/zone_10070,b/zone_10070,b/zone_10070,b/zone_10073,b/zone_10073,b/zone_10073,b/zone_10073,b/zone_10073,,,,,,,,,,,,,,,,b/zone_10072,b/zone_10072,b/zone_10072,b/zone_10072,b/zone_10072,b/zone_10071,b/zone_10071,b/zone_10071,b/zone_10071,b/zone_10071,b/zone_10071
,,b/zone_10074,b/zone_10074,b/zone_10074,b/zone_10074,b/zone_10074,b/zone_10069,b/zone_10069,b/zone_10069,b/zone_10069,b/zone_10069,b/zone_10069,,,,,,,,,,,,,,,,b/zone_10070,b/zone_10070,b/zone_10070,b/zone_10070,b/zone_10070,b/zone_10070,b/zone_10073,b/zone_10073,b/zone_10073,b/zone_10073,b/zone_10073,,,,,,,,,,,,,,,,b/zone_10072,b/zone_10072,b/zone_10072,b/zone_10072,b/zone_10072,b/zone_10071,b/zone_10071,b/zone_10071,b/zone_10071,b/zone_10071,b/zone_10071
,,b/zone_10074,b/zone_10074,b/zone_10074,b/zone_10074,b/zone_10074,,b/zone_10069,b/zone_10069,b/zone_10069,b/zone_10069,b/zone_10069,,,,,,,,,,,,,,,,b/zone_10070,b/zone_10070,b/zone_10070,b/zone_10070,b/zone_10070,,b/zone_10073,b/zone_10073,b/zone_10073,b/zone_10073,b/zone_10073,,,,,,,,,,,,,,,,b/zone_10072,b/zone_10072,b/zone_10072,b/zone_10072,b/zone_10072,,b/zone_10071,b/zone_10071,b/zone_10071,b/zone_10071,b/zone_10071
,,b/zone_10080,b/zone_10080,b/zone_10080,b/zone_10080,b/zone_10080,b/zone_10075,b/zone_10075,b/zone_10075,b/zone_10075,b/zone_10075,b/zone_10075,,,,,,,,,,,,,,,,b/zone_10076,b/zone_10076,b/zone_10076,b/zone_10076,b/zone_10076,b/zone_10076,b/zone_10079,b/zone_10079,b/zone_10079,b/zone_10079,b/zone_10079,,,,,,,,,,,,,,,,b/zone_10078,b/zone_10078,b/zone_10078,b/zone_10078,b/zone_10078,b/zone_10077,b/zone_10077,b/zone_10077,b/zone_10077,b/zone_10077,b/zone_10077
,,b/zone_10080,b/zone_10080,b/zone_10080,b/zone_10080,b/zone_10080,b/zone_10075,b/zone_10075,b/zone_10075,b/zone_10075,b/zone_10075,b/zone_10075,,,,,,,,,,,,,,,,b/zone_10076,b/zone_10076,b/zone_10076,b/zone_10076,b/zone_10076,b/zone_10076,b/zone_10079,b/zone_10079,b/zone_10079,b/zone_10079,b/zone_10079,,,,,,,,,,,,,,,,b/zone_10078,b/zone_10078,b/zone_10078,b/zone_10078,b/zone_10078,b/zone_10077,b/zone_10077,b/zone_10077,b/zone_10077,b/zone_10077,b/zone_10077
,,b/zone_10080,b/zone_10080,b/zone_10080,b/zone_10080,b/zone_10080,b/zone_10075,b/zone_10075,b/zone_10075,b/zone_10075,b/zone_10075,b/zone_10075,,,,,,,,,,,,,,,,b/zone_10076,b/zone_10076,b/zone_10076,b/zone_10076,b/zone_10076,b/zone_10076,b/zone_10079,b/zone_10079,b/zone_10079,b/zone_10079,b/zone_10079,,,,,,,,,,,,,,,,b/zone_10078,b/zone_10078,b/zone_10078,b/zone_10078,b/zone_10078,b/zone_10077,b/zone_10077,b/zone_10077,b/zone_10077,b/zone_10077,b/zone_10077
,,b/zone_10080,b/zone_10080,b/zone_10080,b/zone_10080,b/zone_10080,,b/zone_10075,b/zone_10075,b/zone_10075,b/zone_10075,b/zone_10075,,,,,,,,,,,,,,,,b/zone_10076,b/zone_10076,b/zone_10076,b/zone_10076,b/zone_10076,,b/zone_10079,b/zone_10079,b/zone_10079,b/zone_10079,b/zone_10079,,,,,,,,,,,,,,,,b/zone_10078,b/zone_10078,b/zone_10078,b/zone_10078,b/zone_10078,,b/zone_10077,b/zone_10077,b/zone_10077,b/zone_10077,b/zone_10077
,,b/zone_10086,b/zone_10086,b/zone_10086,b/zone_10086,b/zone_10086,b/zone_10081,b/zone_10081,b/zone_10081,b/zone_10081,b/zone_10081,b/zone_10081,,,,,,,,,,,,,,,,b/zone_10082,b/zone_10082,b/zone_10082,b/zone_10082,b/zone_10082,b/zone_10082,b/zone_10085,b/zone_10085,b/zone_10085,b/zone_10085,b/zone_10085,,,,,,,,,,,,,,,,b/zone_10084,b/zone_10084,b/zone_10084,b/zone_10084,b/zone_10084,b/zone_10083,b/zone_10083,b/zone_10083,b/zone_10083,b/zone_10083,b/zone_10083
,,b/zone_10086,b/zone_10086,b/zone_10086,b/zone_10086,b/zone_10086,b/zone_10081,b/zone_10081,b/zone_10081,b/zone_10081,b/zone_10081,b/zone_10081,,,,,,,,,,,,,,,,b/zone_10082,b/zone_10082,b/zone_10082,b/zone_10082,b/zone_10082,b/zone_10082,b/zone_10085,b/zone_10085,b/zone_10085,b/zone_10085,b/zone_10085,,,,,,,,,,,,,,,,b/zone_10084,b/zone_10084,b/zone_10084,b/zone_10084,b/zone_10084,b/zone_10083,b/zone_10083,b/zone_10083,b/zone_10083,b/zone_10083,b/zone_10083
,,b/zone_10086,b/zone_10086,b/zone_10086,b/zone_10086,b/zone_10086,b/zone_10081,b/zone_10081,b/zone_10081,b/zone_10081,b/zone_10081,b/zone_10081,,,,,,,,,,,,,,,,b/zone_10082,b/zone_10082,b/zone_10082,b/zone_10082,b/zone_10082,b/zone_10082,b/zone_10085,b/zone_10085,b/zone_10085,b/zone_10085,b/zone_10085,,,,,,,,,,,,,,,,b/zone_10084,b/zone_10084,b/zone_10084,b/zone_10084,b/zone_10084,b/zone_10083,b/zone_10083,b/zone_10083,b/zone_10083,b/zone_10083,b/zone_10083
,,b/zone_10086,b/zone_10086,b/zone_10086,b/zone_10086,b/zone_10086,,b/zone_10081,b/zone_10081,b/zone_10081,b/zone_10081,b/zone_10081,b/zone_10094,b/zone_10094,b/zone_10094,b/zone_10094,b/zone_10095,b/zone_10095,b/zone_10095,b/zone_10095,b/zone_10096,b/zone_10096,b/zone_10096,b/zone_10087,b/zone_10087,b/zone_10087,b/zone_10087,b/zone_10082,b/zone_10082,b/zone_10082,b/zone_10082,b/zone_10082,,b/zone_10085,b/zone_10085,b/zone_10085,b/zone_10085,b/zone_10085,b/zone_10088,b/zone_10088,b/zone_10088,b/zone_10088,b/zone_10089,b/zone_10089,b/zone_10089,b/zone_10089,b/zone_10090,b/zone_10090,b/zone_10090,b/zone_10090,b/zone_10091,b/zone_10091,b/zone_10091,b/zone_10084,b/zone_10084,b/zone_10084,b/zone_10084,b/zone_10084,,b/zone_10083,b/zone_10083,b/zone_10083,b/zone_10083,b/zone_10083
,,b/zone_10098,b/zone_10098,b/zone_10098,b/zone_10098,b/zone_10098,b/zone_10093,b/zone_10093,b/zone_10093,b/zone_10093,b/zone_10093,b/zone_10093,b/zone_10094,b/zone_10094,b/zone_10094,b/zone_10094,b/zone_10095,b/zone_10095,b/zone_10095,b/zone_10095,b/zone_10096,b/zone_10096,b/zone_10096,b/zone_10087,b/zone_10087,b/zone_10087,b/zone_10087,b/zone_10087,b/zone_10100,b/zone_10100,b/zone_10100,b/zone_10100,b/zone_10099,b/zone_10099,b/zone_10099,b/zone_10099,b/zone_10099,b/zone_10088,b/zone_10088,b/zone_10088,b/zone_10088,b/zone_10088,b/zone_10089,b/zone_10089,b/zone_10089,b/zone_10089,b/zone_10090,b/zone_10090,b/zone_10090,b/zone_10090,b/zone_10091,b/zone_10091,b/zone_10091,b/zone_10091,b/zone_10092,b/zone_10092,b/zone_10092,b/zone_10092,b/zone_10092,b/zone_10097,b/zone_10097,b/zone_10097,b/zone_10097,b/zone_10097
,,b/zone_10098,b/zone_10098,b/zone_10098,b/zone_10098,b/zone_10098,b/zone_10093,b/zone_10093,b/zone_10093,b/zone_10093,b/zone_10093,b/zone_10093,b/zone_10094,b/zone_10094,b/zone_10094,b/zone_10094,b/zone_10095,b/zone_10095,b/zone_10095,b/zone_10095,b/zone_10096,b/zone_10096,b/zone_10096,b/zone_10087,b/zone_10087,b/zone_10087,b/zone_10087,b/zone_10087,b/zone_10100,b/zone_10100,b/zone_10100,b/zone_10100,b/zone_10099,b/zone_10099,b/zone_10099,b/zone_10099,b/zone_10099,b/zone_10088,b/zone_10088,b/zone_10088,b/zone_10088,b/zone_10088,b/zone_10089,b/zone_10089,b/zone_10089,b/zone_10089,b/zone_10090,b/zone_10090,b/zone_10090,b/zone_10090,b/zone_10091,b/zone_10091,b/zone_10091,b/zone_10091,b/zone_10092,b/zone_10092,b/zone_10092,b/zone_10092,b/zone_10092,b/zone_10097,b/zone_10097,b/zone_10097,b/zone_10097,b/zone_10097
,,b/zone_10098,b/zone_10098,b/zone_10098,b/zone_10098,b/zone_10098,b/zone_10093,b/zone_10093,b/zone_10093,b/zone_10093,b/zone_10093,b/zone_10093,b/zone_10094,b/zone_10094,b/zone_10094,b/zone_10094,b/zone_10095,b/zone_10095,b/zone_10095,b/zone_10095,b/zone_10096,b/zone_10096,b/zone_10096,b/zone_10087,b/zone_10087,b/zone_10087,b/zone_10087,b/zone_10087,b/zone_10100,b/zone_10100,b/zone_10100,b/zone_10100,b/zone_10099,b/zone_10099,b/zone_10099,b/zone_10099,b/zone_10099,b/zone_10088,b/zone_10088,b/zone_10088,b/zone_10088,b/zone_10088,b/zone_10089,b/zone_10089,b/zone_10089,b/zone_10089,b/zone_10090,b/zone_10090,b/zone_10090,b/zone_10090,b/zone_10091,b/zone_10091,b/zone_10091,b/zone_10091,b/zone_10092,b/zone_10092,b/zone_10092,b/zone_10092,b/zone_10092,b/zone_10097,b/zone_10097,b/zone_10097,b/zone_10097,b/zone_10097
,,b/zone_10098,b/zone_10098,b/zone_10098,b/zone_10098,b/zone_10098,,b/zone_10093,b/zone_10093,b/zone_10093,b/zone_10093,b/zone_10093,b/zone_10094,b/zone_10094,b/zone_10094,b/zone_10094,b/zone_10095,b/zone_10095,b/zone_10095,b/zone_10095,b/zone_10096,b/zone_10096,b/zone_10096,b/zone_10087,b/zone_10087,b/zone_10087,b/zone_10087,b/zone_10087,b/zone_10100,b/zone_10100,b/zone_10100,b/zone_10100,,b/zone_10099,b/zone_10099,b/zone_10099,b/zone_10099,b/zone_10088,b/zone_10088,b/zone_10088,b/zone_10088,b/zone_10088,b/zone_10089,b/zone_10089,b/zone_10089,b/zone_10089,b/zone_10090,b/zone_10090,b/zone_10090,b/zone_10090,b/zone_10091,b/zone_10091,b/zone_10091,b/zone_10091,b/zone_10092,b/zone_10092,b/zone_10092,b/zone_10092,,b/zone_10097,b/zone_10097,b/zone_10097,b/zone_10097,b/zone_10097
,,,,,,,,,b/zone_10093,b/zone_10093,b/zone_10093,,b/zone_10094,b/zone_10094,b/zone_10094,,b/zone_10095,b/zone_10095,b/zone_10095,,b/zone_10096,b/zone_10096,b/zone_10096,,b/zone_10087,b/zone_10087,b/zone_10087,,,,,,,,,,,,b/zone_10088,b/zone_10088,b/zone_10088,,b/zone_10089,b/zone_10089,b/zone_10089,,b/zone_10090,b/zone_10090,b/zone_10090,,b/zone_10091,b/zone_10091,b/zone_10091,,b/zone_10092,b/zone_10092,b/zone_10092
,,,,,,,,b/zone_10103,b/zone_10103,b/zone_10103,b/zone_10103,b/zone_10103,b/zone_10105,b/zone_10105,b/zone_10105,b/zone_10105,b/zone_10107,b/zone_10107,b/zone_10107,b/zone_10107,b/zone_10109,b/zone_10109,b/zone_10109,b/zone_10101,b/zone_10101,b/zone_10101,b/zone_10101,b/zone_10101,,,,,,,,,,b/zone_10102,b/zone_10102,b/zone_10102,b/zone_10102,b/zone_10102,b/zone_10104,b/zone_10104,b/zone_10104,b/zone_10104,b/zone_10106,b/zone_10106,b/zone_10106,b/zone_10106,b/zone_10108,b/zone_10108,b/zone_10108,b/zone_10108,b/zone_10110,b/zone_10110,b/zone_10110,b/zone_10110
,,,,,,,,b/zone_10103,b/zone_10103,b/zone_10103,b/zone_10103,b/zone_10103,b/zone_10105,b/zone_10105,b/zone_10105,b/zone_10105,b/zone_10107,b/zone_10107,b/zone_10107,b/zone_10107,b/zone_10109,b/zone_10109,b/zone_10109,b/zone_10101,b/zone_10101,b/zone_10101,b/zone_10101,b/zone_10101,,,,,,,,,,b/zone_10102,b/zone_10102,b/zone_10102,b/zone_10102,b/zone_10102,b/zone_10104,b/zone_10104,b/zone_10104,b/zone_10104,b/zone_10106,b/zone_10106,b/zone_10106,b/zone_10106,b/zone_10108,b/zone_10108,b/zone_10108,b/zone_10108,b/zone_10110,b/zone_10110,b/zone_10110,b/zone_10110
,,,,,,,,b/zone_10103,b/zone_10103,b/zone_10103,b/zone_10103,b/zone_10103,b/zone_10105,b/zone_10105,b/zone_10105,b/zone_10105,b/zone_10107,b/zone_10107,b/zone_10107,b/zone_10107,b/zone_10109,b/zone_10109,b/zone_10109,b/zone_10101,b/zone_10101,b/zone_10101,b/zone_10101,b/zone_10101,,,,,,,,,,b/zone_10102,b/zone_10102,b/zone_10102,b/zone_10102,b/zone_10102,b/zone_10104,b/zone_10104,b/zone_10104,b/zone_10104,b/zone_10106,b/zone_10106,b/zone_10106,b/zone_10106,b/zone_10108,b/zone_10108,b/zone_10108,b/zone_10108,b/zone_10110,b/zone_10110,b/zone_10110,b/zone_10110
,,,,,,,,b/zone_10103,b/zone_10103,b/zone_10103,b/zone_10103,b/zone_10103,b/zone_10105,b/zone_10105,b/zone_10105,b/zone_10105,b/zone_10107,b/zone_10107,b/zone_10107,b/zone_10107,b/zone_10109,b/zone_10109,b/zone_10109,b/zone_10101,b/zone_10101,b/zone_10101,b/zone_10101,b/zone_10101,,,,,,,,,,b/zone_10102,b/zone_10102,b/zone_10102,b/zone_10102,b/zone_10102,b/zone_10104,b/zone_10104,b/zone_10104,b/zone_10104,b/zone_10106,b/zone_10106,b/zone_10106,b/zone_10106,b/zone_10108,b/zone_10108,b/zone_10108,b/zone_10108,b/zone_10110,b/zone_10110,b/zone_10110,b/zone_10110
,,,,,,,,b/zone_10103,b/zone_10103,b/zone_10103,b/zone_10103,b/zone_10103,b/zone_10105,b/zone_10105,b/zone_10105,b/zone_10105,b/zone_10107,b/zone_10107,b/zone_10107,b/zone_10107,b/zone_10109,b/zone_10109,b/zone_10109,b/zone_10101,b/zone_10101,b/zone_10101,b/zone_10101,b/zone_10101,,,,,,,,,,b/zone_10102,b/zone_10102,b/zone_10102,b/zone_10102,b/zone_10102,b/zone_10104,b/zone_10104,b/zone_10104,b/zone_10104,b/zone_10106,b/zone_10106,b/zone_10106,b/zone_10106,b/zone_10108,b/zone_10108,b/zone_10108,b/zone_10108,b/zone_10110,b/zone_10110,b/zone_10110,b/zone_10110
#notes
title: 320 3x3 Bedrooms 3 layer apartment with spiral stairs
author: Gladius
"tags: bedroom, housing, apartment"
"description: Builds a series of bedrooms across 3 layers, with spiral stairs on the sides, for a total of 320 bedrooms."
